2023-06-26 05:18:48,276	[ERROR]	/home/app_admin/venv_private_diary/lib64/python3.8/site-packages/django/core/handlers/exception.py(Line:99)	Invalid HTTP_HOST header: '18.213.182.163'. You may need to add '18.213.182.163' to ALLOWED_HOSTS.
2023-06-26 05:18:48,276	[WARNING]	/home/app_admin/venv_private_diary/lib64/python3.8/site-packages/django/utils/log.py(Line:224)	Bad Request: /favicon.ico
2023-06-26 05:52:18,800	[WARNING]	/home/app_admin/venv_private_diary/lib64/python3.8/site-packages/django/utils/log.py(Line:224)	Not Found: /robots.txt
2023-06-26 06:37:35,558	[ERROR]	/home/app_admin/venv_private_diary/lib64/python3.8/site-packages/django/core/handlers/exception.py(Line:99)	Invalid HTTP_HOST header: '18.213.182.163'. You may need to add '18.213.182.163' to ALLOWED_HOSTS.
2023-06-26 06:37:35,558	[WARNING]	/home/app_admin/venv_private_diary/lib64/python3.8/site-packages/django/utils/log.py(Line:224)	Bad Request: /.env
2023-06-26 06:37:35,913	[ERROR]	/home/app_admin/venv_private_diary/lib64/python3.8/site-packages/django/core/handlers/exception.py(Line:99)	Invalid HTTP_HOST header: '18.213.182.163'. You may need to add '18.213.182.163' to ALLOWED_HOSTS.
2023-06-26 06:37:35,914	[WARNING]	/home/app_admin/venv_private_diary/lib64/python3.8/site-packages/django/utils/log.py(Line:224)	Bad Request: /
2023-06-26 07:02:50,781	[ERROR]	/home/app_admin/venv_private_diary/lib64/python3.8/site-packages/django/core/handlers/exception.py(Line:99)	Invalid HTTP_HOST header: '18.213.182.163'. You may need to add '18.213.182.163' to ALLOWED_HOSTS.
2023-06-26 07:02:50,781	[WARNING]	/home/app_admin/venv_private_diary/lib64/python3.8/site-packages/django/utils/log.py(Line:224)	Bad Request: /
2023-06-26 08:05:39,426	[WARNING]	/home/app_admin/venv_private_diary/lib64/python3.8/site-packages/django/utils/log.py(Line:224)	Not Found: /dist/js/bootstrap.bundle.min.js
2023-06-26 08:05:39,976	[WARNING]	/home/app_admin/venv_private_diary/lib64/python3.8/site-packages/django/utils/log.py(Line:224)	Not Found: //cdn.js
2023-06-26 08:05:41,762	[WARNING]	/home/app_admin/venv_private_diary/lib64/python3.8/site-packages/django/utils/log.py(Line:224)	Not Found: //use.fontawesome.com/releases/v5.15.3/js/all.js
2023-06-26 08:06:19,760	[ERROR]	/home/app_admin/venv_private_diary/lib64/python3.8/site-packages/django/core/handlers/exception.py(Line:99)	Invalid HTTP_HOST header: '18.213.182.163'. You may need to add '18.213.182.163' to ALLOWED_HOSTS.
2023-06-26 08:06:19,760	[WARNING]	/home/app_admin/venv_private_diary/lib64/python3.8/site-packages/django/utils/log.py(Line:224)	Bad Request: /
2023-06-26 08:20:29,456	[ERROR]	/home/app_admin/venv_private_diary/lib64/python3.8/site-packages/django/core/handlers/exception.py(Line:99)	Invalid HTTP_HOST header: '18.213.182.163'. You may need to add '18.213.182.163' to ALLOWED_HOSTS.
2023-06-26 08:20:29,457	[WARNING]	/home/app_admin/venv_private_diary/lib64/python3.8/site-packages/django/utils/log.py(Line:224)	Bad Request: /actuator/health
2023-06-26 08:36:27,412	[ERROR]	/home/app_admin/venv_private_diary/lib64/python3.8/site-packages/django/core/handlers/exception.py(Line:99)	Invalid HTTP_HOST header: '18.213.182.163'. You may need to add '18.213.182.163' to ALLOWED_HOSTS.
2023-06-26 08:36:27,412	[WARNING]	/home/app_admin/venv_private_diary/lib64/python3.8/site-packages/django/utils/log.py(Line:224)	Bad Request: /.env
2023-06-26 08:36:27,777	[ERROR]	/home/app_admin/venv_private_diary/lib64/python3.8/site-packages/django/core/handlers/exception.py(Line:99)	Invalid HTTP_HOST header: '18.213.182.163'. You may need to add '18.213.182.163' to ALLOWED_HOSTS.
2023-06-26 08:36:27,777	[WARNING]	/home/app_admin/venv_private_diary/lib64/python3.8/site-packages/django/utils/log.py(Line:224)	Bad Request: /
2023-06-26 08:47:56,938	[ERROR]	/home/app_admin/venv_private_diary/lib64/python3.8/site-packages/django/core/handlers/exception.py(Line:99)	Invalid HTTP_HOST header: '18.213.182.163'. You may need to add '18.213.182.163' to ALLOWED_HOSTS.
2023-06-26 08:47:56,938	[WARNING]	/home/app_admin/venv_private_diary/lib64/python3.8/site-packages/django/utils/log.py(Line:224)	Bad Request: /
2023-06-26 10:16:43,562	[ERROR]	/home/app_admin/venv_private_diary/lib64/python3.8/site-packages/django/core/handlers/exception.py(Line:99)	Invalid HTTP_HOST header: '18.213.182.163'. You may need to add '18.213.182.163' to ALLOWED_HOSTS.
2023-06-26 10:16:43,562	[WARNING]	/home/app_admin/venv_private_diary/lib64/python3.8/site-packages/django/utils/log.py(Line:224)	Bad Request: /
2023-06-26 12:00:10,971	[ERROR]	/home/app_admin/venv_private_diary/lib64/python3.8/site-packages/django/core/handlers/exception.py(Line:99)	Invalid HTTP_HOST header: '18.213.182.163:443'. You may need to add '18.213.182.163' to ALLOWED_HOSTS.
2023-06-26 12:00:10,971	[WARNING]	/home/app_admin/venv_private_diary/lib64/python3.8/site-packages/django/utils/log.py(Line:224)	Bad Request: /
2023-06-26 12:19:45,336	[ERROR]	/home/app_admin/venv_private_diary/lib64/python3.8/site-packages/django/core/handlers/exception.py(Line:99)	Invalid HTTP_HOST header: '18.213.182.163'. You may need to add '18.213.182.163' to ALLOWED_HOSTS.
2023-06-26 12:19:45,336	[WARNING]	/home/app_admin/venv_private_diary/lib64/python3.8/site-packages/django/utils/log.py(Line:224)	Bad Request: /ecp/Current/exporttool/microsoft.exchange.ediscovery.exporttool.application
2023-06-26 12:26:56,985	[ERROR]	/home/app_admin/venv_private_diary/lib64/python3.8/site-packages/django/core/handlers/exception.py(Line:99)	Invalid HTTP_HOST header: '18.213.182.163'. You may need to add '18.213.182.163' to ALLOWED_HOSTS.
2023-06-26 12:26:56,985	[WARNING]	/home/app_admin/venv_private_diary/lib64/python3.8/site-packages/django/utils/log.py(Line:224)	Bad Request: /.env
2023-06-26 12:26:57,352	[ERROR]	/home/app_admin/venv_private_diary/lib64/python3.8/site-packages/django/core/handlers/exception.py(Line:99)	Invalid HTTP_HOST header: '18.213.182.163'. You may need to add '18.213.182.163' to ALLOWED_HOSTS.
2023-06-26 12:26:57,353	[WARNING]	/home/app_admin/venv_private_diary/lib64/python3.8/site-packages/django/utils/log.py(Line:224)	Bad Request: /
2023-06-26 13:04:09,449	[ERROR]	/home/app_admin/venv_private_diary/lib64/python3.8/site-packages/django/core/handlers/exception.py(Line:99)	Invalid HTTP_HOST header: '18.213.182.163:443'. You may need to add '18.213.182.163' to ALLOWED_HOSTS.
2023-06-26 13:04:09,450	[WARNING]	/home/app_admin/venv_private_diary/lib64/python3.8/site-packages/django/utils/log.py(Line:224)	Bad Request: /
2023-06-26 13:10:19,670	[ERROR]	/home/app_admin/venv_private_diary/lib64/python3.8/site-packages/django/core/handlers/exception.py(Line:99)	Invalid HTTP_HOST header: '18.213.182.163'. You may need to add '18.213.182.163' to ALLOWED_HOSTS.
2023-06-26 13:10:19,671	[WARNING]	/home/app_admin/venv_private_diary/lib64/python3.8/site-packages/django/utils/log.py(Line:224)	Bad Request: /
2023-06-26 13:18:35,878	[ERROR]	/home/app_admin/venv_private_diary/lib64/python3.8/site-packages/django/core/handlers/exception.py(Line:99)	Invalid HTTP_HOST header: '18.213.182.163'. You may need to add '18.213.182.163' to ALLOWED_HOSTS.
2023-06-26 13:18:35,879	[WARNING]	/home/app_admin/venv_private_diary/lib64/python3.8/site-packages/django/utils/log.py(Line:224)	Bad Request: /dns-query
2023-06-26 13:20:57,300	[ERROR]	/home/app_admin/venv_private_diary/lib64/python3.8/site-packages/django/core/handlers/exception.py(Line:99)	Invalid HTTP_HOST header: '18.213.182.163'. You may need to add '18.213.182.163' to ALLOWED_HOSTS.
2023-06-26 13:20:57,301	[WARNING]	/home/app_admin/venv_private_diary/lib64/python3.8/site-packages/django/utils/log.py(Line:224)	Bad Request: /geoserver/web/
2023-06-26 13:21:31,416	[ERROR]	/home/app_admin/venv_private_diary/lib64/python3.8/site-packages/django/core/handlers/exception.py(Line:99)	Invalid HTTP_HOST header: '18.213.182.163'. You may need to add '18.213.182.163' to ALLOWED_HOSTS.
2023-06-26 13:21:31,416	[WARNING]	/home/app_admin/venv_private_diary/lib64/python3.8/site-packages/django/utils/log.py(Line:224)	Bad Request: /.git/config
2023-06-26 13:28:57,936	[ERROR]	/home/app_admin/venv_private_diary/lib64/python3.8/site-packages/django/core/handlers/exception.py(Line:99)	Invalid HTTP_HOST header: '18.213.182.163:443'. You may need to add '18.213.182.163' to ALLOWED_HOSTS.
2023-06-26 13:28:57,936	[WARNING]	/home/app_admin/venv_private_diary/lib64/python3.8/site-packages/django/utils/log.py(Line:224)	Bad Request: /
2023-06-26 13:51:57,907	[ERROR]	/home/app_admin/venv_private_diary/lib64/python3.8/site-packages/django/core/handlers/exception.py(Line:99)	Invalid HTTP_HOST header: '18.213.182.163'. You may need to add '18.213.182.163' to ALLOWED_HOSTS.
2023-06-26 13:51:57,907	[WARNING]	/home/app_admin/venv_private_diary/lib64/python3.8/site-packages/django/utils/log.py(Line:224)	Bad Request: /
2023-06-26 13:53:06,162	[ERROR]	/home/app_admin/venv_private_diary/lib64/python3.8/site-packages/django/core/handlers/exception.py(Line:99)	Invalid HTTP_HOST header: '18.213.182.163'. You may need to add '18.213.182.163' to ALLOWED_HOSTS.
2023-06-26 13:53:06,162	[WARNING]	/home/app_admin/venv_private_diary/lib64/python3.8/site-packages/django/utils/log.py(Line:224)	Bad Request: /.env
2023-06-26 13:53:07,212	[ERROR]	/home/app_admin/venv_private_diary/lib64/python3.8/site-packages/django/core/handlers/exception.py(Line:99)	Invalid HTTP_HOST header: '18.213.182.163'. You may need to add '18.213.182.163' to ALLOWED_HOSTS.
2023-06-26 13:53:07,213	[WARNING]	/home/app_admin/venv_private_diary/lib64/python3.8/site-packages/django/utils/log.py(Line:224)	Bad Request: /
2023-06-26 13:53:14,996	[ERROR]	/home/app_admin/venv_private_diary/lib64/python3.8/site-packages/django/core/handlers/exception.py(Line:99)	Invalid HTTP_HOST header: '18.213.182.163'. You may need to add '18.213.182.163' to ALLOWED_HOSTS.
2023-06-26 13:53:14,997	[WARNING]	/home/app_admin/venv_private_diary/lib64/python3.8/site-packages/django/utils/log.py(Line:224)	Bad Request: /vendor/phpunit/phpunit/src/Util/PHP/eval-stdin.php
2023-06-26 13:59:08,780	[ERROR]	/home/app_admin/venv_private_diary/lib64/python3.8/site-packages/django/core/handlers/exception.py(Line:99)	Invalid HTTP_HOST header: '18.213.182.163'. You may need to add '18.213.182.163' to ALLOWED_HOSTS.
2023-06-26 13:59:08,780	[WARNING]	/home/app_admin/venv_private_diary/lib64/python3.8/site-packages/django/utils/log.py(Line:224)	Bad Request: /
2023-06-26 14:12:34,170	[ERROR]	/home/app_admin/venv_private_diary/lib64/python3.8/site-packages/django/core/handlers/exception.py(Line:99)	Invalid HTTP_HOST header: '169.254.169.254'. You may need to add '169.254.169.254' to ALLOWED_HOSTS.
2023-06-26 14:12:34,170	[WARNING]	/home/app_admin/venv_private_diary/lib64/python3.8/site-packages/django/utils/log.py(Line:224)	Bad Request: /latest/meta-data/
2023-06-26 14:13:31,131	[ERROR]	/home/app_admin/venv_private_diary/lib64/python3.8/site-packages/django/core/handlers/exception.py(Line:99)	Invalid HTTP_HOST header: '18.213.182.163'. You may need to add '18.213.182.163' to ALLOWED_HOSTS.
2023-06-26 14:13:31,132	[WARNING]	/home/app_admin/venv_private_diary/lib64/python3.8/site-packages/django/utils/log.py(Line:224)	Bad Request: /.env
2023-06-26 14:13:31,490	[ERROR]	/home/app_admin/venv_private_diary/lib64/python3.8/site-packages/django/core/handlers/exception.py(Line:99)	Invalid HTTP_HOST header: '18.213.182.163'. You may need to add '18.213.182.163' to ALLOWED_HOSTS.
2023-06-26 14:13:31,490	[WARNING]	/home/app_admin/venv_private_diary/lib64/python3.8/site-packages/django/utils/log.py(Line:224)	Bad Request: /
2023-06-26 16:06:47,254	[ERROR]	/home/app_admin/venv_private_diary/lib64/python3.8/site-packages/django/core/handlers/exception.py(Line:99)	Invalid HTTP_HOST header: '18.213.182.163'. You may need to add '18.213.182.163' to ALLOWED_HOSTS.
2023-06-26 16:06:47,254	[WARNING]	/home/app_admin/venv_private_diary/lib64/python3.8/site-packages/django/utils/log.py(Line:224)	Bad Request: /
2023-06-26 16:07:42,094	[ERROR]	/home/app_admin/venv_private_diary/lib64/python3.8/site-packages/django/core/handlers/exception.py(Line:99)	Invalid HTTP_HOST header: '18.213.182.163'. You may need to add '18.213.182.163' to ALLOWED_HOSTS.
2023-06-26 16:07:42,094	[WARNING]	/home/app_admin/venv_private_diary/lib64/python3.8/site-packages/django/utils/log.py(Line:224)	Bad Request: /
2023-06-26 16:45:46,614	[ERROR]	/home/app_admin/venv_private_diary/lib64/python3.8/site-packages/django/core/handlers/exception.py(Line:99)	Invalid HTTP_HOST header: '18.213.182.163'. You may need to add '18.213.182.163' to ALLOWED_HOSTS.
2023-06-26 16:45:46,615	[WARNING]	/home/app_admin/venv_private_diary/lib64/python3.8/site-packages/django/utils/log.py(Line:224)	Bad Request: /.env
2023-06-26 16:52:08,026	[ERROR]	/home/app_admin/venv_private_diary/lib64/python3.8/site-packages/django/core/handlers/exception.py(Line:99)	Invalid HTTP_HOST header: '18.213.182.163'. You may need to add '18.213.182.163' to ALLOWED_HOSTS.
2023-06-26 16:52:08,026	[WARNING]	/home/app_admin/venv_private_diary/lib64/python3.8/site-packages/django/utils/log.py(Line:224)	Bad Request: /
2023-06-26 17:02:30,069	[ERROR]	/home/app_admin/venv_private_diary/lib64/python3.8/site-packages/django/core/handlers/exception.py(Line:99)	Invalid HTTP_HOST header: '18.213.182.163'. You may need to add '18.213.182.163' to ALLOWED_HOSTS.
2023-06-26 17:02:30,070	[WARNING]	/home/app_admin/venv_private_diary/lib64/python3.8/site-packages/django/utils/log.py(Line:224)	Bad Request: /.env
2023-06-26 17:02:30,426	[ERROR]	/home/app_admin/venv_private_diary/lib64/python3.8/site-packages/django/core/handlers/exception.py(Line:99)	Invalid HTTP_HOST header: '18.213.182.163'. You may need to add '18.213.182.163' to ALLOWED_HOSTS.
2023-06-26 17:02:30,426	[WARNING]	/home/app_admin/venv_private_diary/lib64/python3.8/site-packages/django/utils/log.py(Line:224)	Bad Request: /
2023-06-26 17:11:36,716	[ERROR]	/home/app_admin/venv_private_diary/lib64/python3.8/site-packages/django/core/handlers/exception.py(Line:99)	Invalid HTTP_HOST header: '18.213.182.163'. You may need to add '18.213.182.163' to ALLOWED_HOSTS.
2023-06-26 17:11:36,716	[WARNING]	/home/app_admin/venv_private_diary/lib64/python3.8/site-packages/django/utils/log.py(Line:224)	Bad Request: /
2023-06-26 17:17:33,915	[WARNING]	/home/app_admin/venv_private_diary/lib64/python3.8/site-packages/django/utils/log.py(Line:224)	Not Found: /controre
2023-06-26 17:17:39,979	[WARNING]	/home/app_admin/venv_private_diary/lib64/python3.8/site-packages/django/utils/log.py(Line:224)	Not Found: /controlle
2023-06-26 17:46:08,393	[ERROR]	/home/app_admin/venv_private_diary/lib64/python3.8/site-packages/django/core/handlers/exception.py(Line:99)	Invalid HTTP_HOST header: '18.213.182.163'. You may need to add '18.213.182.163' to ALLOWED_HOSTS.
2023-06-26 17:46:08,393	[WARNING]	/home/app_admin/venv_private_diary/lib64/python3.8/site-packages/django/utils/log.py(Line:224)	Bad Request: /
2023-06-26 19:01:00,608	[ERROR]	/home/app_admin/venv_private_diary/lib64/python3.8/site-packages/django/core/handlers/exception.py(Line:99)	Invalid HTTP_HOST header: '18.213.182.163'. You may need to add '18.213.182.163' to ALLOWED_HOSTS.
2023-06-26 19:01:00,608	[WARNING]	/home/app_admin/venv_private_diary/lib64/python3.8/site-packages/django/utils/log.py(Line:224)	Bad Request: /.env
2023-06-26 19:01:00,720	[ERROR]	/home/app_admin/venv_private_diary/lib64/python3.8/site-packages/django/core/handlers/exception.py(Line:99)	Invalid HTTP_HOST header: '18.213.182.163'. You may need to add '18.213.182.163' to ALLOWED_HOSTS.
2023-06-26 19:01:00,720	[WARNING]	/home/app_admin/venv_private_diary/lib64/python3.8/site-packages/django/utils/log.py(Line:224)	Bad Request: /
2023-06-26 20:20:20,471	[ERROR]	/home/app_admin/venv_private_diary/lib64/python3.8/site-packages/django/core/handlers/exception.py(Line:99)	Invalid HTTP_HOST header: '18.213.182.163'. You may need to add '18.213.182.163' to ALLOWED_HOSTS.
2023-06-26 20:20:20,472	[WARNING]	/home/app_admin/venv_private_diary/lib64/python3.8/site-packages/django/utils/log.py(Line:224)	Bad Request: /.env
2023-06-26 20:20:20,835	[ERROR]	/home/app_admin/venv_private_diary/lib64/python3.8/site-packages/django/core/handlers/exception.py(Line:99)	Invalid HTTP_HOST header: '18.213.182.163'. You may need to add '18.213.182.163' to ALLOWED_HOSTS.
2023-06-26 20:20:20,836	[WARNING]	/home/app_admin/venv_private_diary/lib64/python3.8/site-packages/django/utils/log.py(Line:224)	Bad Request: /
2023-06-26 20:36:29,194	[ERROR]	/home/app_admin/venv_private_diary/lib64/python3.8/site-packages/django/core/handlers/exception.py(Line:99)	Invalid HTTP_HOST header: '18.213.182.163'. You may need to add '18.213.182.163' to ALLOWED_HOSTS.
2023-06-26 20:36:29,195	[WARNING]	/home/app_admin/venv_private_diary/lib64/python3.8/site-packages/django/utils/log.py(Line:224)	Bad Request: //wp-includes/ID3/license.txt
2023-06-26 20:36:29,296	[ERROR]	/home/app_admin/venv_private_diary/lib64/python3.8/site-packages/django/core/handlers/exception.py(Line:99)	Invalid HTTP_HOST header: '18.213.182.163'. You may need to add '18.213.182.163' to ALLOWED_HOSTS.
2023-06-26 20:36:29,297	[WARNING]	/home/app_admin/venv_private_diary/lib64/python3.8/site-packages/django/utils/log.py(Line:224)	Bad Request: //feed/
2023-06-26 20:36:29,410	[ERROR]	/home/app_admin/venv_private_diary/lib64/python3.8/site-packages/django/core/handlers/exception.py(Line:99)	Invalid HTTP_HOST header: '18.213.182.163'. You may need to add '18.213.182.163' to ALLOWED_HOSTS.
2023-06-26 20:36:29,410	[WARNING]	/home/app_admin/venv_private_diary/lib64/python3.8/site-packages/django/utils/log.py(Line:224)	Bad Request: //xmlrpc.php
2023-06-26 20:36:29,511	[ERROR]	/home/app_admin/venv_private_diary/lib64/python3.8/site-packages/django/core/handlers/exception.py(Line:99)	Invalid HTTP_HOST header: '18.213.182.163'. You may need to add '18.213.182.163' to ALLOWED_HOSTS.
2023-06-26 20:36:29,511	[WARNING]	/home/app_admin/venv_private_diary/lib64/python3.8/site-packages/django/utils/log.py(Line:224)	Bad Request: //blog/wp-includes/wlwmanifest.xml
2023-06-26 20:36:29,617	[ERROR]	/home/app_admin/venv_private_diary/lib64/python3.8/site-packages/django/core/handlers/exception.py(Line:99)	Invalid HTTP_HOST header: '18.213.182.163'. You may need to add '18.213.182.163' to ALLOWED_HOSTS.
2023-06-26 20:36:29,617	[WARNING]	/home/app_admin/venv_private_diary/lib64/python3.8/site-packages/django/utils/log.py(Line:224)	Bad Request: //web/wp-includes/wlwmanifest.xml
2023-06-26 20:36:29,737	[ERROR]	/home/app_admin/venv_private_diary/lib64/python3.8/site-packages/django/core/handlers/exception.py(Line:99)	Invalid HTTP_HOST header: '18.213.182.163'. You may need to add '18.213.182.163' to ALLOWED_HOSTS.
2023-06-26 20:36:29,737	[WARNING]	/home/app_admin/venv_private_diary/lib64/python3.8/site-packages/django/utils/log.py(Line:224)	Bad Request: //wordpress/wp-includes/wlwmanifest.xml
2023-06-26 20:36:29,838	[ERROR]	/home/app_admin/venv_private_diary/lib64/python3.8/site-packages/django/core/handlers/exception.py(Line:99)	Invalid HTTP_HOST header: '18.213.182.163'. You may need to add '18.213.182.163' to ALLOWED_HOSTS.
2023-06-26 20:36:29,838	[WARNING]	/home/app_admin/venv_private_diary/lib64/python3.8/site-packages/django/utils/log.py(Line:224)	Bad Request: //wp/wp-includes/wlwmanifest.xml
2023-06-26 20:36:29,957	[ERROR]	/home/app_admin/venv_private_diary/lib64/python3.8/site-packages/django/core/handlers/exception.py(Line:99)	Invalid HTTP_HOST header: '18.213.182.163'. You may need to add '18.213.182.163' to ALLOWED_HOSTS.
2023-06-26 20:36:29,957	[WARNING]	/home/app_admin/venv_private_diary/lib64/python3.8/site-packages/django/utils/log.py(Line:224)	Bad Request: //2020/wp-includes/wlwmanifest.xml
2023-06-26 20:36:30,058	[ERROR]	/home/app_admin/venv_private_diary/lib64/python3.8/site-packages/django/core/handlers/exception.py(Line:99)	Invalid HTTP_HOST header: '18.213.182.163'. You may need to add '18.213.182.163' to ALLOWED_HOSTS.
2023-06-26 20:36:30,058	[WARNING]	/home/app_admin/venv_private_diary/lib64/python3.8/site-packages/django/utils/log.py(Line:224)	Bad Request: //2019/wp-includes/wlwmanifest.xml
2023-06-26 20:36:30,159	[ERROR]	/home/app_admin/venv_private_diary/lib64/python3.8/site-packages/django/core/handlers/exception.py(Line:99)	Invalid HTTP_HOST header: '18.213.182.163'. You may need to add '18.213.182.163' to ALLOWED_HOSTS.
2023-06-26 20:36:30,159	[WARNING]	/home/app_admin/venv_private_diary/lib64/python3.8/site-packages/django/utils/log.py(Line:224)	Bad Request: //2021/wp-includes/wlwmanifest.xml
2023-06-26 20:36:30,260	[ERROR]	/home/app_admin/venv_private_diary/lib64/python3.8/site-packages/django/core/handlers/exception.py(Line:99)	Invalid HTTP_HOST header: '18.213.182.163'. You may need to add '18.213.182.163' to ALLOWED_HOSTS.
2023-06-26 20:36:30,260	[WARNING]	/home/app_admin/venv_private_diary/lib64/python3.8/site-packages/django/utils/log.py(Line:224)	Bad Request: //shop/wp-includes/wlwmanifest.xml
2023-06-26 20:36:30,364	[ERROR]	/home/app_admin/venv_private_diary/lib64/python3.8/site-packages/django/core/handlers/exception.py(Line:99)	Invalid HTTP_HOST header: '18.213.182.163'. You may need to add '18.213.182.163' to ALLOWED_HOSTS.
2023-06-26 20:36:30,365	[WARNING]	/home/app_admin/venv_private_diary/lib64/python3.8/site-packages/django/utils/log.py(Line:224)	Bad Request: //wp1/wp-includes/wlwmanifest.xml
2023-06-26 20:36:30,465	[ERROR]	/home/app_admin/venv_private_diary/lib64/python3.8/site-packages/django/core/handlers/exception.py(Line:99)	Invalid HTTP_HOST header: '18.213.182.163'. You may need to add '18.213.182.163' to ALLOWED_HOSTS.
2023-06-26 20:36:30,465	[WARNING]	/home/app_admin/venv_private_diary/lib64/python3.8/site-packages/django/utils/log.py(Line:224)	Bad Request: //test/wp-includes/wlwmanifest.xml
2023-06-26 20:36:30,566	[ERROR]	/home/app_admin/venv_private_diary/lib64/python3.8/site-packages/django/core/handlers/exception.py(Line:99)	Invalid HTTP_HOST header: '18.213.182.163'. You may need to add '18.213.182.163' to ALLOWED_HOSTS.
2023-06-26 20:36:30,566	[WARNING]	/home/app_admin/venv_private_diary/lib64/python3.8/site-packages/django/utils/log.py(Line:224)	Bad Request: //site/wp-includes/wlwmanifest.xml
2023-06-26 20:36:30,666	[ERROR]	/home/app_admin/venv_private_diary/lib64/python3.8/site-packages/django/core/handlers/exception.py(Line:99)	Invalid HTTP_HOST header: '18.213.182.163'. You may need to add '18.213.182.163' to ALLOWED_HOSTS.
2023-06-26 20:36:30,667	[WARNING]	/home/app_admin/venv_private_diary/lib64/python3.8/site-packages/django/utils/log.py(Line:224)	Bad Request: //cms/wp-includes/wlwmanifest.xml
2023-06-26 21:12:59,955	[ERROR]	/home/app_admin/venv_private_diary/lib64/python3.8/site-packages/django/core/handlers/exception.py(Line:99)	Invalid HTTP_HOST header: '18.213.182.163'. You may need to add '18.213.182.163' to ALLOWED_HOSTS.
2023-06-26 21:12:59,956	[WARNING]	/home/app_admin/venv_private_diary/lib64/python3.8/site-packages/django/utils/log.py(Line:224)	Bad Request: /CACHE/sdesktop/data.xml
2023-06-26 21:14:33,607	[ERROR]	/home/app_admin/venv_private_diary/lib64/python3.8/site-packages/django/core/handlers/exception.py(Line:99)	Invalid HTTP_HOST header: '18.213.182.163'. You may need to add '18.213.182.163' to ALLOWED_HOSTS.
2023-06-26 21:14:33,607	[WARNING]	/home/app_admin/venv_private_diary/lib64/python3.8/site-packages/django/utils/log.py(Line:224)	Bad Request: /
2023-06-26 21:55:15,024	[ERROR]	/home/app_admin/venv_private_diary/lib64/python3.8/site-packages/django/core/handlers/exception.py(Line:99)	Invalid HTTP_HOST header: '18.213.182.163'. You may need to add '18.213.182.163' to ALLOWED_HOSTS.
2023-06-26 21:55:15,024	[WARNING]	/home/app_admin/venv_private_diary/lib64/python3.8/site-packages/django/utils/log.py(Line:224)	Bad Request: /.env
2023-06-26 21:55:15,413	[ERROR]	/home/app_admin/venv_private_diary/lib64/python3.8/site-packages/django/core/handlers/exception.py(Line:99)	Invalid HTTP_HOST header: '18.213.182.163'. You may need to add '18.213.182.163' to ALLOWED_HOSTS.
2023-06-26 21:55:15,413	[WARNING]	/home/app_admin/venv_private_diary/lib64/python3.8/site-packages/django/utils/log.py(Line:224)	Bad Request: /
2023-06-26 21:57:43,684	[ERROR]	/home/app_admin/venv_private_diary/lib64/python3.8/site-packages/django/core/handlers/exception.py(Line:99)	Invalid HTTP_HOST header: '18.213.182.163'. You may need to add '18.213.182.163' to ALLOWED_HOSTS.
2023-06-26 21:57:43,685	[WARNING]	/home/app_admin/venv_private_diary/lib64/python3.8/site-packages/django/utils/log.py(Line:224)	Bad Request: /
2023-06-26 22:00:45,544	[WARNING]	/home/app_admin/venv_private_diary/lib64/python3.8/site-packages/django/utils/log.py(Line:224)	Not Found: /wp-content/plugins/bookit/readme.txt
2023-06-26 23:39:06,033	[ERROR]	/home/app_admin/venv_private_diary/lib64/python3.8/site-packages/django/core/handlers/exception.py(Line:99)	Invalid HTTP_HOST header: '18.213.182.163'. You may need to add '18.213.182.163' to ALLOWED_HOSTS.
2023-06-26 23:39:06,034	[WARNING]	/home/app_admin/venv_private_diary/lib64/python3.8/site-packages/django/utils/log.py(Line:224)	Bad Request: /.env
2023-06-26 23:39:06,422	[ERROR]	/home/app_admin/venv_private_diary/lib64/python3.8/site-packages/django/core/handlers/exception.py(Line:99)	Invalid HTTP_HOST header: '18.213.182.163'. You may need to add '18.213.182.163' to ALLOWED_HOSTS.
2023-06-26 23:39:06,423	[WARNING]	/home/app_admin/venv_private_diary/lib64/python3.8/site-packages/django/utils/log.py(Line:224)	Bad Request: /
2023-06-27 00:56:29,713	[ERROR]	/home/app_admin/venv_private_diary/lib64/python3.8/site-packages/django/core/handlers/exception.py(Line:99)	Invalid HTTP_HOST header: '18.213.182.163'. You may need to add '18.213.182.163' to ALLOWED_HOSTS.
2023-06-27 00:56:29,714	[WARNING]	/home/app_admin/venv_private_diary/lib64/python3.8/site-packages/django/utils/log.py(Line:224)	Bad Request: /favicon.ico
2023-06-27 02:40:54,656	[ERROR]	/home/app_admin/venv_private_diary/lib64/python3.8/site-packages/django/core/handlers/exception.py(Line:99)	Invalid HTTP_HOST header: '18.213.182.163'. You may need to add '18.213.182.163' to ALLOWED_HOSTS.
2023-06-27 02:40:54,657	[WARNING]	/home/app_admin/venv_private_diary/lib64/python3.8/site-packages/django/utils/log.py(Line:224)	Bad Request: /autodiscover/autodiscover.json
2023-06-27 02:52:20,250	[ERROR]	/home/app_admin/venv_private_diary/lib64/python3.8/site-packages/django/core/handlers/exception.py(Line:99)	Invalid HTTP_HOST header: '18.213.182.163'. You may need to add '18.213.182.163' to ALLOWED_HOSTS.
2023-06-27 02:52:20,251	[WARNING]	/home/app_admin/venv_private_diary/lib64/python3.8/site-packages/django/utils/log.py(Line:224)	Bad Request: /.env
2023-06-27 03:36:22,939	[ERROR]	/home/app_admin/venv_private_diary/lib64/python3.8/site-packages/django/core/handlers/exception.py(Line:99)	Invalid HTTP_HOST header: '18.213.182.163'. You may need to add '18.213.182.163' to ALLOWED_HOSTS.
2023-06-27 03:36:22,940	[WARNING]	/home/app_admin/venv_private_diary/lib64/python3.8/site-packages/django/utils/log.py(Line:224)	Bad Request: /
2023-06-27 03:36:53,064	[ERROR]	/home/app_admin/venv_private_diary/lib64/python3.8/site-packages/django/core/handlers/exception.py(Line:99)	Invalid HTTP_HOST header: '18.213.182.163'. You may need to add '18.213.182.163' to ALLOWED_HOSTS.
2023-06-27 03:36:53,064	[WARNING]	/home/app_admin/venv_private_diary/lib64/python3.8/site-packages/django/utils/log.py(Line:224)	Bad Request: /dns-query
2023-06-27 03:46:08,070	[ERROR]	/home/app_admin/venv_private_diary/lib64/python3.8/site-packages/django/core/handlers/exception.py(Line:99)	Invalid HTTP_HOST header: '18.213.182.163'. You may need to add '18.213.182.163' to ALLOWED_HOSTS.
2023-06-27 03:46:08,071	[WARNING]	/home/app_admin/venv_private_diary/lib64/python3.8/site-packages/django/utils/log.py(Line:224)	Bad Request: /
2023-06-27 03:46:08,132	[ERROR]	/home/app_admin/venv_private_diary/lib64/python3.8/site-packages/django/core/handlers/exception.py(Line:99)	Invalid HTTP_HOST header: '18.213.182.163'. You may need to add '18.213.182.163' to ALLOWED_HOSTS.
2023-06-27 03:46:08,132	[WARNING]	/home/app_admin/venv_private_diary/lib64/python3.8/site-packages/django/utils/log.py(Line:224)	Bad Request: /
2023-06-27 04:00:46,147	[ERROR]	/home/app_admin/venv_private_diary/lib64/python3.8/site-packages/django/core/handlers/exception.py(Line:99)	Invalid HTTP_HOST header: '18.213.182.163'. You may need to add '18.213.182.163' to ALLOWED_HOSTS.
2023-06-27 04:00:46,148	[WARNING]	/home/app_admin/venv_private_diary/lib64/python3.8/site-packages/django/utils/log.py(Line:224)	Bad Request: /remote/login
2023-06-27 04:45:47,420	[ERROR]	/home/app_admin/venv_private_diary/lib64/python3.8/site-packages/django/core/handlers/exception.py(Line:99)	Invalid HTTP_HOST header: '18.213.182.163:443'. You may need to add '18.213.182.163' to ALLOWED_HOSTS.
2023-06-27 04:45:47,420	[WARNING]	/home/app_admin/venv_private_diary/lib64/python3.8/site-packages/django/utils/log.py(Line:224)	Bad Request: /
2023-06-27 05:17:31,977	[ERROR]	/home/app_admin/venv_private_diary/lib64/python3.8/site-packages/django/core/handlers/exception.py(Line:99)	Invalid HTTP_HOST header: '18.213.182.163'. You may need to add '18.213.182.163' to ALLOWED_HOSTS.
2023-06-27 05:17:31,977	[WARNING]	/home/app_admin/venv_private_diary/lib64/python3.8/site-packages/django/utils/log.py(Line:224)	Bad Request: /.env
2023-06-27 05:17:32,512	[ERROR]	/home/app_admin/venv_private_diary/lib64/python3.8/site-packages/django/core/handlers/exception.py(Line:99)	Invalid HTTP_HOST header: '18.213.182.163'. You may need to add '18.213.182.163' to ALLOWED_HOSTS.
2023-06-27 05:17:32,513	[WARNING]	/home/app_admin/venv_private_diary/lib64/python3.8/site-packages/django/utils/log.py(Line:224)	Bad Request: /
2023-06-27 05:43:21,928	[ERROR]	/home/app_admin/venv_private_diary/lib64/python3.8/site-packages/django/core/handlers/exception.py(Line:99)	Invalid HTTP_HOST header: '18.213.182.163'. You may need to add '18.213.182.163' to ALLOWED_HOSTS.
2023-06-27 05:43:21,928	[WARNING]	/home/app_admin/venv_private_diary/lib64/python3.8/site-packages/django/utils/log.py(Line:224)	Bad Request: /
2023-06-27 05:43:49,346	[WARNING]	/home/app_admin/venv_private_diary/lib64/python3.8/site-packages/django/utils/log.py(Line:224)	Not Found: /robots.txt
2023-06-27 06:29:36,792	[ERROR]	/home/app_admin/venv_private_diary/lib64/python3.8/site-packages/django/core/handlers/exception.py(Line:99)	Invalid HTTP_HOST header: '18.213.182.163'. You may need to add '18.213.182.163' to ALLOWED_HOSTS.
2023-06-27 06:29:36,793	[WARNING]	/home/app_admin/venv_private_diary/lib64/python3.8/site-packages/django/utils/log.py(Line:224)	Bad Request: /remote/logincheck
2023-06-27 06:33:28,821	[ERROR]	/home/app_admin/venv_private_diary/lib64/python3.8/site-packages/django/core/handlers/exception.py(Line:99)	Invalid HTTP_HOST header: '18.213.182.163'. You may need to add '18.213.182.163' to ALLOWED_HOSTS.
2023-06-27 06:33:28,821	[WARNING]	/home/app_admin/venv_private_diary/lib64/python3.8/site-packages/django/utils/log.py(Line:224)	Bad Request: /favicon.ico
2023-06-27 06:34:50,638	[ERROR]	/home/app_admin/venv_private_diary/lib64/python3.8/site-packages/django/core/handlers/exception.py(Line:99)	Invalid HTTP_HOST header: '18.213.182.163'. You may need to add '18.213.182.163' to ALLOWED_HOSTS.
2023-06-27 06:34:50,638	[WARNING]	/home/app_admin/venv_private_diary/lib64/python3.8/site-packages/django/utils/log.py(Line:224)	Bad Request: /
2023-06-27 06:47:05,878	[ERROR]	/home/app_admin/venv_private_diary/lib64/python3.8/site-packages/django/core/handlers/exception.py(Line:99)	Invalid HTTP_HOST header: '18.213.182.163'. You may need to add '18.213.182.163' to ALLOWED_HOSTS.
2023-06-27 06:47:05,878	[WARNING]	/home/app_admin/venv_private_diary/lib64/python3.8/site-packages/django/utils/log.py(Line:224)	Bad Request: /
2023-06-27 06:48:19,819	[WARNING]	/home/app_admin/venv_private_diary/lib64/python3.8/site-packages/django/utils/log.py(Line:224)	Not Found: //wp-includes/wlwmanifest.xml
2023-06-27 06:48:20,105	[WARNING]	/home/app_admin/venv_private_diary/lib64/python3.8/site-packages/django/utils/log.py(Line:224)	Not Found: //xmlrpc.php
2023-06-27 06:48:21,636	[WARNING]	/home/app_admin/venv_private_diary/lib64/python3.8/site-packages/django/utils/log.py(Line:224)	Not Found: //blog/wp-includes/wlwmanifest.xml
2023-06-27 06:48:21,890	[WARNING]	/home/app_admin/venv_private_diary/lib64/python3.8/site-packages/django/utils/log.py(Line:224)	Not Found: //web/wp-includes/wlwmanifest.xml
2023-06-27 06:48:22,143	[WARNING]	/home/app_admin/venv_private_diary/lib64/python3.8/site-packages/django/utils/log.py(Line:224)	Not Found: //wordpress/wp-includes/wlwmanifest.xml
2023-06-27 06:48:22,399	[WARNING]	/home/app_admin/venv_private_diary/lib64/python3.8/site-packages/django/utils/log.py(Line:224)	Not Found: //website/wp-includes/wlwmanifest.xml
2023-06-27 06:48:22,707	[WARNING]	/home/app_admin/venv_private_diary/lib64/python3.8/site-packages/django/utils/log.py(Line:224)	Not Found: //wp/wp-includes/wlwmanifest.xml
2023-06-27 06:48:22,982	[WARNING]	/home/app_admin/venv_private_diary/lib64/python3.8/site-packages/django/utils/log.py(Line:224)	Not Found: //news/wp-includes/wlwmanifest.xml
2023-06-27 06:48:23,235	[WARNING]	/home/app_admin/venv_private_diary/lib64/python3.8/site-packages/django/utils/log.py(Line:224)	Not Found: //2020/wp-includes/wlwmanifest.xml
2023-06-27 06:48:23,486	[WARNING]	/home/app_admin/venv_private_diary/lib64/python3.8/site-packages/django/utils/log.py(Line:224)	Not Found: //2019/wp-includes/wlwmanifest.xml
2023-06-27 06:48:23,792	[WARNING]	/home/app_admin/venv_private_diary/lib64/python3.8/site-packages/django/utils/log.py(Line:224)	Not Found: //shop/wp-includes/wlwmanifest.xml
2023-06-27 06:48:26,255	[WARNING]	/home/app_admin/venv_private_diary/lib64/python3.8/site-packages/django/utils/log.py(Line:224)	Not Found: //wp1/wp-includes/wlwmanifest.xml
2023-06-27 06:48:26,520	[WARNING]	/home/app_admin/venv_private_diary/lib64/python3.8/site-packages/django/utils/log.py(Line:224)	Not Found: //test/wp-includes/wlwmanifest.xml
2023-06-27 06:48:26,775	[WARNING]	/home/app_admin/venv_private_diary/lib64/python3.8/site-packages/django/utils/log.py(Line:224)	Not Found: //wp2/wp-includes/wlwmanifest.xml
2023-06-27 06:48:27,027	[WARNING]	/home/app_admin/venv_private_diary/lib64/python3.8/site-packages/django/utils/log.py(Line:224)	Not Found: //site/wp-includes/wlwmanifest.xml
2023-06-27 06:48:27,282	[WARNING]	/home/app_admin/venv_private_diary/lib64/python3.8/site-packages/django/utils/log.py(Line:224)	Not Found: //cms/wp-includes/wlwmanifest.xml
2023-06-27 06:48:27,555	[WARNING]	/home/app_admin/venv_private_diary/lib64/python3.8/site-packages/django/utils/log.py(Line:224)	Not Found: //sito/wp-includes/wlwmanifest.xml
2023-06-27 07:27:07,581	[ERROR]	/home/app_admin/venv_private_diary/lib64/python3.8/site-packages/django/core/handlers/exception.py(Line:99)	Invalid HTTP_HOST header: '18.213.182.163'. You may need to add '18.213.182.163' to ALLOWED_HOSTS.
2023-06-27 07:27:07,582	[WARNING]	/home/app_admin/venv_private_diary/lib64/python3.8/site-packages/django/utils/log.py(Line:224)	Bad Request: /
2023-06-27 07:27:26,973	[ERROR]	/home/app_admin/venv_private_diary/lib64/python3.8/site-packages/django/core/handlers/exception.py(Line:99)	Invalid HTTP_HOST header: '18.213.182.163'. You may need to add '18.213.182.163' to ALLOWED_HOSTS.
2023-06-27 07:27:26,973	[WARNING]	/home/app_admin/venv_private_diary/lib64/python3.8/site-packages/django/utils/log.py(Line:224)	Bad Request: /favicon.ico
2023-06-27 07:27:28,930	[ERROR]	/home/app_admin/venv_private_diary/lib64/python3.8/site-packages/django/core/handlers/exception.py(Line:99)	Invalid HTTP_HOST header: '18.213.182.163'. You may need to add '18.213.182.163' to ALLOWED_HOSTS.
2023-06-27 07:27:28,930	[WARNING]	/home/app_admin/venv_private_diary/lib64/python3.8/site-packages/django/utils/log.py(Line:224)	Bad Request: /robots.txt
2023-06-27 07:27:30,585	[ERROR]	/home/app_admin/venv_private_diary/lib64/python3.8/site-packages/django/core/handlers/exception.py(Line:99)	Invalid HTTP_HOST header: '18.213.182.163'. You may need to add '18.213.182.163' to ALLOWED_HOSTS.
2023-06-27 07:27:30,586	[WARNING]	/home/app_admin/venv_private_diary/lib64/python3.8/site-packages/django/utils/log.py(Line:224)	Bad Request: /sitemap.xml
2023-06-27 07:42:32,562	[ERROR]	/home/app_admin/venv_private_diary/lib64/python3.8/site-packages/django/core/handlers/exception.py(Line:99)	Invalid HTTP_HOST header: '18.213.182.163'. You may need to add '18.213.182.163' to ALLOWED_HOSTS.
2023-06-27 07:42:32,562	[WARNING]	/home/app_admin/venv_private_diary/lib64/python3.8/site-packages/django/utils/log.py(Line:224)	Bad Request: /.env
2023-06-27 07:42:33,297	[ERROR]	/home/app_admin/venv_private_diary/lib64/python3.8/site-packages/django/core/handlers/exception.py(Line:99)	Invalid HTTP_HOST header: '18.213.182.163'. You may need to add '18.213.182.163' to ALLOWED_HOSTS.
2023-06-27 07:42:33,297	[WARNING]	/home/app_admin/venv_private_diary/lib64/python3.8/site-packages/django/utils/log.py(Line:224)	Bad Request: /
2023-06-27 09:30:54,608	[WARNING]	/home/app_admin/venv_private_diary/lib64/python3.8/site-packages/django/utils/log.py(Line:224)	Not Found: //wp-includes/wlwmanifest.xml
2023-06-27 09:30:54,842	[WARNING]	/home/app_admin/venv_private_diary/lib64/python3.8/site-packages/django/utils/log.py(Line:224)	Not Found: //xmlrpc.php
2023-06-27 09:30:55,351	[WARNING]	/home/app_admin/venv_private_diary/lib64/python3.8/site-packages/django/utils/log.py(Line:224)	Not Found: //blog/wp-includes/wlwmanifest.xml
2023-06-27 09:30:55,600	[WARNING]	/home/app_admin/venv_private_diary/lib64/python3.8/site-packages/django/utils/log.py(Line:224)	Not Found: //web/wp-includes/wlwmanifest.xml
2023-06-27 09:30:55,835	[WARNING]	/home/app_admin/venv_private_diary/lib64/python3.8/site-packages/django/utils/log.py(Line:224)	Not Found: //wordpress/wp-includes/wlwmanifest.xml
2023-06-27 09:30:56,069	[WARNING]	/home/app_admin/venv_private_diary/lib64/python3.8/site-packages/django/utils/log.py(Line:224)	Not Found: //website/wp-includes/wlwmanifest.xml
2023-06-27 09:30:56,303	[WARNING]	/home/app_admin/venv_private_diary/lib64/python3.8/site-packages/django/utils/log.py(Line:224)	Not Found: //wp/wp-includes/wlwmanifest.xml
2023-06-27 09:30:56,537	[WARNING]	/home/app_admin/venv_private_diary/lib64/python3.8/site-packages/django/utils/log.py(Line:224)	Not Found: //news/wp-includes/wlwmanifest.xml
2023-06-27 09:30:56,771	[WARNING]	/home/app_admin/venv_private_diary/lib64/python3.8/site-packages/django/utils/log.py(Line:224)	Not Found: //2018/wp-includes/wlwmanifest.xml
2023-06-27 09:30:57,005	[WARNING]	/home/app_admin/venv_private_diary/lib64/python3.8/site-packages/django/utils/log.py(Line:224)	Not Found: //2019/wp-includes/wlwmanifest.xml
2023-06-27 09:30:57,239	[WARNING]	/home/app_admin/venv_private_diary/lib64/python3.8/site-packages/django/utils/log.py(Line:224)	Not Found: //shop/wp-includes/wlwmanifest.xml
2023-06-27 09:30:57,492	[WARNING]	/home/app_admin/venv_private_diary/lib64/python3.8/site-packages/django/utils/log.py(Line:224)	Not Found: //wp1/wp-includes/wlwmanifest.xml
2023-06-27 09:30:57,726	[WARNING]	/home/app_admin/venv_private_diary/lib64/python3.8/site-packages/django/utils/log.py(Line:224)	Not Found: //test/wp-includes/wlwmanifest.xml
2023-06-27 09:30:58,191	[WARNING]	/home/app_admin/venv_private_diary/lib64/python3.8/site-packages/django/utils/log.py(Line:224)	Not Found: //wp2/wp-includes/wlwmanifest.xml
2023-06-27 09:30:58,425	[WARNING]	/home/app_admin/venv_private_diary/lib64/python3.8/site-packages/django/utils/log.py(Line:224)	Not Found: //site/wp-includes/wlwmanifest.xml
2023-06-27 09:30:58,659	[WARNING]	/home/app_admin/venv_private_diary/lib64/python3.8/site-packages/django/utils/log.py(Line:224)	Not Found: //cms/wp-includes/wlwmanifest.xml
2023-06-27 09:30:58,893	[WARNING]	/home/app_admin/venv_private_diary/lib64/python3.8/site-packages/django/utils/log.py(Line:224)	Not Found: //sito/wp-includes/wlwmanifest.xml
2023-06-27 10:44:05,021	[ERROR]	/home/app_admin/venv_private_diary/lib64/python3.8/site-packages/django/core/handlers/exception.py(Line:99)	Invalid HTTP_HOST header: '18.213.182.163'. You may need to add '18.213.182.163' to ALLOWED_HOSTS.
2023-06-27 10:44:05,021	[WARNING]	/home/app_admin/venv_private_diary/lib64/python3.8/site-packages/django/utils/log.py(Line:224)	Bad Request: /
2023-06-27 10:45:02,785	[ERROR]	/home/app_admin/venv_private_diary/lib64/python3.8/site-packages/django/core/handlers/exception.py(Line:99)	Invalid HTTP_HOST header: '18.213.182.163'. You may need to add '18.213.182.163' to ALLOWED_HOSTS.
2023-06-27 10:45:02,785	[WARNING]	/home/app_admin/venv_private_diary/lib64/python3.8/site-packages/django/utils/log.py(Line:224)	Bad Request: /
2023-06-27 10:48:49,836	[ERROR]	/home/app_admin/venv_private_diary/lib64/python3.8/site-packages/django/core/handlers/exception.py(Line:99)	Invalid HTTP_HOST header: '18.213.182.163:443'. You may need to add '18.213.182.163' to ALLOWED_HOSTS.
2023-06-27 10:48:49,836	[WARNING]	/home/app_admin/venv_private_diary/lib64/python3.8/site-packages/django/utils/log.py(Line:224)	Bad Request: /
2023-06-27 11:20:34,740	[ERROR]	/home/app_admin/venv_private_diary/lib64/python3.8/site-packages/django/core/handlers/exception.py(Line:99)	Invalid HTTP_HOST header: '18.213.182.163:443'. You may need to add '18.213.182.163' to ALLOWED_HOSTS.
2023-06-27 11:20:34,740	[WARNING]	/home/app_admin/venv_private_diary/lib64/python3.8/site-packages/django/utils/log.py(Line:224)	Bad Request: /
2023-06-27 11:24:00,878	[ERROR]	/home/app_admin/venv_private_diary/lib64/python3.8/site-packages/django/core/handlers/exception.py(Line:99)	Invalid HTTP_HOST header: '18.213.182.163'. You may need to add '18.213.182.163' to ALLOWED_HOSTS.
2023-06-27 11:24:00,878	[WARNING]	/home/app_admin/venv_private_diary/lib64/python3.8/site-packages/django/utils/log.py(Line:224)	Bad Request: /
2023-06-27 11:49:29,073	[ERROR]	/home/app_admin/venv_private_diary/lib64/python3.8/site-packages/django/utils/log.py(Line:224)	Internal Server Error: /diary-ai/
Traceback (most recent call last):
  File "/home/app_admin/venv_private_diary/lib64/python3.8/site-packages/django/core/handlers/exception.py", line 47, in inner
    response = get_response(request)
  File "/home/app_admin/venv_private_diary/lib64/python3.8/site-packages/django/core/handlers/base.py", line 181, in _get_response
    response = wrapped_callback(request, *callback_args, **callback_kwargs)
  File "/home/app_admin/venv_private_diary/lib64/python3.8/site-packages/django/views/generic/base.py", line 70, in view
    return self.dispatch(request, *args, **kwargs)
  File "/home/app_admin/venv_private_diary/lib64/python3.8/site-packages/django/contrib/auth/mixins.py", line 71, in dispatch
    return super().dispatch(request, *args, **kwargs)
  File "/home/app_admin/venv_private_diary/lib64/python3.8/site-packages/django/views/generic/base.py", line 98, in dispatch
    return handler(request, *args, **kwargs)
  File "/home/app_admin/venv_private_diary/lib64/python3.8/site-packages/django/views/generic/edit.py", line 142, in post
    return self.form_valid(form)
  File "/home/app_admin/venv_private_diary/private_diary/diary/views.py", line 135, in form_valid
    response_content = openai.ChatCompletion.create(
  File "/home/app_admin/venv_private_diary/lib64/python3.8/site-packages/openai/api_resources/chat_completion.py", line 25, in create
    return super().create(*args, **kwargs)
  File "/home/app_admin/venv_private_diary/lib64/python3.8/site-packages/openai/api_resources/abstract/engine_api_resource.py", line 153, in create
    response, _, api_key = requestor.request(
  File "/home/app_admin/venv_private_diary/lib64/python3.8/site-packages/openai/api_requestor.py", line 226, in request
    resp, got_stream = self._interpret_response(result, stream)
  File "/home/app_admin/venv_private_diary/lib64/python3.8/site-packages/openai/api_requestor.py", line 620, in _interpret_response
    self._interpret_response_line(
  File "/home/app_admin/venv_private_diary/lib64/python3.8/site-packages/openai/api_requestor.py", line 663, in _interpret_response_line
    raise error.ServiceUnavailableError(
openai.error.ServiceUnavailableError: The server is overloaded or not ready yet.
2023-06-27 11:50:18,830	[ERROR]	/home/app_admin/venv_private_diary/lib64/python3.8/site-packages/django/utils/log.py(Line:224)	Internal Server Error: /diary-ai/
Traceback (most recent call last):
  File "/home/app_admin/venv_private_diary/lib64/python3.8/site-packages/django/core/handlers/exception.py", line 47, in inner
    response = get_response(request)
  File "/home/app_admin/venv_private_diary/lib64/python3.8/site-packages/django/core/handlers/base.py", line 181, in _get_response
    response = wrapped_callback(request, *callback_args, **callback_kwargs)
  File "/home/app_admin/venv_private_diary/lib64/python3.8/site-packages/django/views/generic/base.py", line 70, in view
    return self.dispatch(request, *args, **kwargs)
  File "/home/app_admin/venv_private_diary/lib64/python3.8/site-packages/django/contrib/auth/mixins.py", line 71, in dispatch
    return super().dispatch(request, *args, **kwargs)
  File "/home/app_admin/venv_private_diary/lib64/python3.8/site-packages/django/views/generic/base.py", line 98, in dispatch
    return handler(request, *args, **kwargs)
  File "/home/app_admin/venv_private_diary/lib64/python3.8/site-packages/django/views/generic/edit.py", line 142, in post
    return self.form_valid(form)
  File "/home/app_admin/venv_private_diary/private_diary/diary/views.py", line 166, in form_valid
    response_title = openai.ChatCompletion.create(
  File "/home/app_admin/venv_private_diary/lib64/python3.8/site-packages/openai/api_resources/chat_completion.py", line 25, in create
    return super().create(*args, **kwargs)
  File "/home/app_admin/venv_private_diary/lib64/python3.8/site-packages/openai/api_resources/abstract/engine_api_resource.py", line 153, in create
    response, _, api_key = requestor.request(
  File "/home/app_admin/venv_private_diary/lib64/python3.8/site-packages/openai/api_requestor.py", line 226, in request
    resp, got_stream = self._interpret_response(result, stream)
  File "/home/app_admin/venv_private_diary/lib64/python3.8/site-packages/openai/api_requestor.py", line 620, in _interpret_response
    self._interpret_response_line(
  File "/home/app_admin/venv_private_diary/lib64/python3.8/site-packages/openai/api_requestor.py", line 663, in _interpret_response_line
    raise error.ServiceUnavailableError(
openai.error.ServiceUnavailableError: The server is overloaded or not ready yet.
2023-06-27 11:51:45,887	[ERROR]	/home/app_admin/venv_private_diary/lib64/python3.8/site-packages/django/utils/log.py(Line:224)	Internal Server Error: /diary-create/
Traceback (most recent call last):
  File "/home/app_admin/venv_private_diary/lib64/python3.8/site-packages/django/db/backends/utils.py", line 84, in _execute
    return self.cursor.execute(sql, params)
psycopg2.errors.NotNullViolation: リレーション"diary_diary"の列"event"のNULL値がが非NULL制約に違反しています
DETAIL:  失敗した行は(23, 「犬と過ごした充実した一日」, 今日はとても楽しい一日だった。朝早くから犬..., , , , 2023-06-27 02:51:45.878955+00, 2023-06-27 02:51:45.878972+00, 14, null, , null, null, null, null, null)を含みます


The above exception was the direct cause of the following exception:

Traceback (most recent call last):
  File "/home/app_admin/venv_private_diary/lib64/python3.8/site-packages/django/core/handlers/exception.py", line 47, in inner
    response = get_response(request)
  File "/home/app_admin/venv_private_diary/lib64/python3.8/site-packages/django/core/handlers/base.py", line 181, in _get_response
    response = wrapped_callback(request, *callback_args, **callback_kwargs)
  File "/home/app_admin/venv_private_diary/lib64/python3.8/site-packages/django/views/generic/base.py", line 70, in view
    return self.dispatch(request, *args, **kwargs)
  File "/home/app_admin/venv_private_diary/lib64/python3.8/site-packages/django/contrib/auth/mixins.py", line 71, in dispatch
    return super().dispatch(request, *args, **kwargs)
  File "/home/app_admin/venv_private_diary/lib64/python3.8/site-packages/django/views/generic/base.py", line 98, in dispatch
    return handler(request, *args, **kwargs)
  File "/home/app_admin/venv_private_diary/lib64/python3.8/site-packages/django/views/generic/edit.py", line 172, in post
    return super().post(request, *args, **kwargs)
  File "/home/app_admin/venv_private_diary/lib64/python3.8/site-packages/django/views/generic/edit.py", line 142, in post
    return self.form_valid(form)
  File "/home/app_admin/venv_private_diary/private_diary/diary/views.py", line 80, in form_valid
    diary.save()
  File "/home/app_admin/venv_private_diary/lib64/python3.8/site-packages/django/db/models/base.py", line 726, in save
    self.save_base(using=using, force_insert=force_insert,
  File "/home/app_admin/venv_private_diary/lib64/python3.8/site-packages/django/db/models/base.py", line 763, in save_base
    updated = self._save_table(
  File "/home/app_admin/venv_private_diary/lib64/python3.8/site-packages/django/db/models/base.py", line 868, in _save_table
    results = self._do_insert(cls._base_manager, using, fields, returning_fields, raw)
  File "/home/app_admin/venv_private_diary/lib64/python3.8/site-packages/django/db/models/base.py", line 906, in _do_insert
    return manager._insert(
  File "/home/app_admin/venv_private_diary/lib64/python3.8/site-packages/django/db/models/manager.py", line 85, in manager_method
    return getattr(self.get_queryset(), name)(*args, **kwargs)
  File "/home/app_admin/venv_private_diary/lib64/python3.8/site-packages/django/db/models/query.py", line 1270, in _insert
    return query.get_compiler(using=using).execute_sql(returning_fields)
  File "/home/app_admin/venv_private_diary/lib64/python3.8/site-packages/django/db/models/sql/compiler.py", line 1416, in execute_sql
    cursor.execute(sql, params)
  File "/home/app_admin/venv_private_diary/lib64/python3.8/site-packages/django/db/backends/utils.py", line 66, in execute
    return self._execute_with_wrappers(sql, params, many=False, executor=self._execute)
  File "/home/app_admin/venv_private_diary/lib64/python3.8/site-packages/django/db/backends/utils.py", line 75, in _execute_with_wrappers
    return executor(sql, params, many, context)
  File "/home/app_admin/venv_private_diary/lib64/python3.8/site-packages/django/db/backends/utils.py", line 84, in _execute
    return self.cursor.execute(sql, params)
  File "/home/app_admin/venv_private_diary/lib64/python3.8/site-packages/django/db/utils.py", line 90, in __exit__
    raise dj_exc_value.with_traceback(traceback) from exc_value
  File "/home/app_admin/venv_private_diary/lib64/python3.8/site-packages/django/db/backends/utils.py", line 84, in _execute
    return self.cursor.execute(sql, params)
django.db.utils.IntegrityError: リレーション"diary_diary"の列"event"のNULL値がが非NULL制約に違反しています
DETAIL:  失敗した行は(23, 「犬と過ごした充実した一日」, 今日はとても楽しい一日だった。朝早くから犬..., , , , 2023-06-27 02:51:45.878955+00, 2023-06-27 02:51:45.878972+00, 14, null, , null, null, null, null, null)を含みます

2023-06-27 11:51:51,039	[ERROR]	/home/app_admin/venv_private_diary/lib64/python3.8/site-packages/django/utils/log.py(Line:224)	Internal Server Error: /diary-create/
Traceback (most recent call last):
  File "/home/app_admin/venv_private_diary/lib64/python3.8/site-packages/django/db/backends/utils.py", line 84, in _execute
    return self.cursor.execute(sql, params)
psycopg2.errors.NotNullViolation: リレーション"diary_diary"の列"event"のNULL値がが非NULL制約に違反しています
DETAIL:  失敗した行は(24, 「犬と過ごした充実した一日」, 今日はとても楽しい一日だった。朝早くから犬..., , , , 2023-06-27 02:51:51.037528+00, 2023-06-27 02:51:51.037546+00, 14, null, , null, null, null, null, null)を含みます


The above exception was the direct cause of the following exception:

Traceback (most recent call last):
  File "/home/app_admin/venv_private_diary/lib64/python3.8/site-packages/django/core/handlers/exception.py", line 47, in inner
    response = get_response(request)
  File "/home/app_admin/venv_private_diary/lib64/python3.8/site-packages/django/core/handlers/base.py", line 181, in _get_response
    response = wrapped_callback(request, *callback_args, **callback_kwargs)
  File "/home/app_admin/venv_private_diary/lib64/python3.8/site-packages/django/views/generic/base.py", line 70, in view
    return self.dispatch(request, *args, **kwargs)
  File "/home/app_admin/venv_private_diary/lib64/python3.8/site-packages/django/contrib/auth/mixins.py", line 71, in dispatch
    return super().dispatch(request, *args, **kwargs)
  File "/home/app_admin/venv_private_diary/lib64/python3.8/site-packages/django/views/generic/base.py", line 98, in dispatch
    return handler(request, *args, **kwargs)
  File "/home/app_admin/venv_private_diary/lib64/python3.8/site-packages/django/views/generic/edit.py", line 172, in post
    return super().post(request, *args, **kwargs)
  File "/home/app_admin/venv_private_diary/lib64/python3.8/site-packages/django/views/generic/edit.py", line 142, in post
    return self.form_valid(form)
  File "/home/app_admin/venv_private_diary/private_diary/diary/views.py", line 80, in form_valid
    diary.save()
  File "/home/app_admin/venv_private_diary/lib64/python3.8/site-packages/django/db/models/base.py", line 726, in save
    self.save_base(using=using, force_insert=force_insert,
  File "/home/app_admin/venv_private_diary/lib64/python3.8/site-packages/django/db/models/base.py", line 763, in save_base
    updated = self._save_table(
  File "/home/app_admin/venv_private_diary/lib64/python3.8/site-packages/django/db/models/base.py", line 868, in _save_table
    results = self._do_insert(cls._base_manager, using, fields, returning_fields, raw)
  File "/home/app_admin/venv_private_diary/lib64/python3.8/site-packages/django/db/models/base.py", line 906, in _do_insert
    return manager._insert(
  File "/home/app_admin/venv_private_diary/lib64/python3.8/site-packages/django/db/models/manager.py", line 85, in manager_method
    return getattr(self.get_queryset(), name)(*args, **kwargs)
  File "/home/app_admin/venv_private_diary/lib64/python3.8/site-packages/django/db/models/query.py", line 1270, in _insert
    return query.get_compiler(using=using).execute_sql(returning_fields)
  File "/home/app_admin/venv_private_diary/lib64/python3.8/site-packages/django/db/models/sql/compiler.py", line 1416, in execute_sql
    cursor.execute(sql, params)
  File "/home/app_admin/venv_private_diary/lib64/python3.8/site-packages/django/db/backends/utils.py", line 66, in execute
    return self._execute_with_wrappers(sql, params, many=False, executor=self._execute)
  File "/home/app_admin/venv_private_diary/lib64/python3.8/site-packages/django/db/backends/utils.py", line 75, in _execute_with_wrappers
    return executor(sql, params, many, context)
  File "/home/app_admin/venv_private_diary/lib64/python3.8/site-packages/django/db/backends/utils.py", line 84, in _execute
    return self.cursor.execute(sql, params)
  File "/home/app_admin/venv_private_diary/lib64/python3.8/site-packages/django/db/utils.py", line 90, in __exit__
    raise dj_exc_value.with_traceback(traceback) from exc_value
  File "/home/app_admin/venv_private_diary/lib64/python3.8/site-packages/django/db/backends/utils.py", line 84, in _execute
    return self.cursor.execute(sql, params)
django.db.utils.IntegrityError: リレーション"diary_diary"の列"event"のNULL値がが非NULL制約に違反しています
DETAIL:  失敗した行は(24, 「犬と過ごした充実した一日」, 今日はとても楽しい一日だった。朝早くから犬..., , , , 2023-06-27 02:51:51.037528+00, 2023-06-27 02:51:51.037546+00, 14, null, , null, null, null, null, null)を含みます

2023-06-27 11:51:54,321	[ERROR]	/home/app_admin/venv_private_diary/lib64/python3.8/site-packages/django/utils/log.py(Line:224)	Internal Server Error: /diary-create/
Traceback (most recent call last):
  File "/home/app_admin/venv_private_diary/lib64/python3.8/site-packages/django/db/backends/utils.py", line 84, in _execute
    return self.cursor.execute(sql, params)
psycopg2.errors.NotNullViolation: リレーション"diary_diary"の列"event"のNULL値がが非NULL制約に違反しています
DETAIL:  失敗した行は(25, 「犬と過ごした充実した一日」, 今日はとても楽しい一日だった。朝早くから犬..., , , , 2023-06-27 02:51:54.319729+00, 2023-06-27 02:51:54.319747+00, 14, null, , null, null, null, null, null)を含みます


The above exception was the direct cause of the following exception:

Traceback (most recent call last):
  File "/home/app_admin/venv_private_diary/lib64/python3.8/site-packages/django/core/handlers/exception.py", line 47, in inner
    response = get_response(request)
  File "/home/app_admin/venv_private_diary/lib64/python3.8/site-packages/django/core/handlers/base.py", line 181, in _get_response
    response = wrapped_callback(request, *callback_args, **callback_kwargs)
  File "/home/app_admin/venv_private_diary/lib64/python3.8/site-packages/django/views/generic/base.py", line 70, in view
    return self.dispatch(request, *args, **kwargs)
  File "/home/app_admin/venv_private_diary/lib64/python3.8/site-packages/django/contrib/auth/mixins.py", line 71, in dispatch
    return super().dispatch(request, *args, **kwargs)
  File "/home/app_admin/venv_private_diary/lib64/python3.8/site-packages/django/views/generic/base.py", line 98, in dispatch
    return handler(request, *args, **kwargs)
  File "/home/app_admin/venv_private_diary/lib64/python3.8/site-packages/django/views/generic/edit.py", line 172, in post
    return super().post(request, *args, **kwargs)
  File "/home/app_admin/venv_private_diary/lib64/python3.8/site-packages/django/views/generic/edit.py", line 142, in post
    return self.form_valid(form)
  File "/home/app_admin/venv_private_diary/private_diary/diary/views.py", line 80, in form_valid
    diary.save()
  File "/home/app_admin/venv_private_diary/lib64/python3.8/site-packages/django/db/models/base.py", line 726, in save
    self.save_base(using=using, force_insert=force_insert,
  File "/home/app_admin/venv_private_diary/lib64/python3.8/site-packages/django/db/models/base.py", line 763, in save_base
    updated = self._save_table(
  File "/home/app_admin/venv_private_diary/lib64/python3.8/site-packages/django/db/models/base.py", line 868, in _save_table
    results = self._do_insert(cls._base_manager, using, fields, returning_fields, raw)
  File "/home/app_admin/venv_private_diary/lib64/python3.8/site-packages/django/db/models/base.py", line 906, in _do_insert
    return manager._insert(
  File "/home/app_admin/venv_private_diary/lib64/python3.8/site-packages/django/db/models/manager.py", line 85, in manager_method
    return getattr(self.get_queryset(), name)(*args, **kwargs)
  File "/home/app_admin/venv_private_diary/lib64/python3.8/site-packages/django/db/models/query.py", line 1270, in _insert
    return query.get_compiler(using=using).execute_sql(returning_fields)
  File "/home/app_admin/venv_private_diary/lib64/python3.8/site-packages/django/db/models/sql/compiler.py", line 1416, in execute_sql
    cursor.execute(sql, params)
  File "/home/app_admin/venv_private_diary/lib64/python3.8/site-packages/django/db/backends/utils.py", line 66, in execute
    return self._execute_with_wrappers(sql, params, many=False, executor=self._execute)
  File "/home/app_admin/venv_private_diary/lib64/python3.8/site-packages/django/db/backends/utils.py", line 75, in _execute_with_wrappers
    return executor(sql, params, many, context)
  File "/home/app_admin/venv_private_diary/lib64/python3.8/site-packages/django/db/backends/utils.py", line 84, in _execute
    return self.cursor.execute(sql, params)
  File "/home/app_admin/venv_private_diary/lib64/python3.8/site-packages/django/db/utils.py", line 90, in __exit__
    raise dj_exc_value.with_traceback(traceback) from exc_value
  File "/home/app_admin/venv_private_diary/lib64/python3.8/site-packages/django/db/backends/utils.py", line 84, in _execute
    return self.cursor.execute(sql, params)
django.db.utils.IntegrityError: リレーション"diary_diary"の列"event"のNULL値がが非NULL制約に違反しています
DETAIL:  失敗した行は(25, 「犬と過ごした充実した一日」, 今日はとても楽しい一日だった。朝早くから犬..., , , , 2023-06-27 02:51:54.319729+00, 2023-06-27 02:51:54.319747+00, 14, null, , null, null, null, null, null)を含みます

2023-06-27 11:52:03,241	[ERROR]	/home/app_admin/venv_private_diary/lib64/python3.8/site-packages/django/utils/log.py(Line:224)	Internal Server Error: /diary-create/
Traceback (most recent call last):
  File "/home/app_admin/venv_private_diary/lib64/python3.8/site-packages/django/db/backends/utils.py", line 84, in _execute
    return self.cursor.execute(sql, params)
psycopg2.errors.NotNullViolation: リレーション"diary_diary"の列"event"のNULL値がが非NULL制約に違反しています
DETAIL:  失敗した行は(26, fasdfasd, fasd, , , , 2023-06-27 02:52:03.239646+00, 2023-06-27 02:52:03.239666+00, 14, null, , null, null, null, null, null)を含みます


The above exception was the direct cause of the following exception:

Traceback (most recent call last):
  File "/home/app_admin/venv_private_diary/lib64/python3.8/site-packages/django/core/handlers/exception.py", line 47, in inner
    response = get_response(request)
  File "/home/app_admin/venv_private_diary/lib64/python3.8/site-packages/django/core/handlers/base.py", line 181, in _get_response
    response = wrapped_callback(request, *callback_args, **callback_kwargs)
  File "/home/app_admin/venv_private_diary/lib64/python3.8/site-packages/django/views/generic/base.py", line 70, in view
    return self.dispatch(request, *args, **kwargs)
  File "/home/app_admin/venv_private_diary/lib64/python3.8/site-packages/django/contrib/auth/mixins.py", line 71, in dispatch
    return super().dispatch(request, *args, **kwargs)
  File "/home/app_admin/venv_private_diary/lib64/python3.8/site-packages/django/views/generic/base.py", line 98, in dispatch
    return handler(request, *args, **kwargs)
  File "/home/app_admin/venv_private_diary/lib64/python3.8/site-packages/django/views/generic/edit.py", line 172, in post
    return super().post(request, *args, **kwargs)
  File "/home/app_admin/venv_private_diary/lib64/python3.8/site-packages/django/views/generic/edit.py", line 142, in post
    return self.form_valid(form)
  File "/home/app_admin/venv_private_diary/private_diary/diary/views.py", line 80, in form_valid
    diary.save()
  File "/home/app_admin/venv_private_diary/lib64/python3.8/site-packages/django/db/models/base.py", line 726, in save
    self.save_base(using=using, force_insert=force_insert,
  File "/home/app_admin/venv_private_diary/lib64/python3.8/site-packages/django/db/models/base.py", line 763, in save_base
    updated = self._save_table(
  File "/home/app_admin/venv_private_diary/lib64/python3.8/site-packages/django/db/models/base.py", line 868, in _save_table
    results = self._do_insert(cls._base_manager, using, fields, returning_fields, raw)
  File "/home/app_admin/venv_private_diary/lib64/python3.8/site-packages/django/db/models/base.py", line 906, in _do_insert
    return manager._insert(
  File "/home/app_admin/venv_private_diary/lib64/python3.8/site-packages/django/db/models/manager.py", line 85, in manager_method
    return getattr(self.get_queryset(), name)(*args, **kwargs)
  File "/home/app_admin/venv_private_diary/lib64/python3.8/site-packages/django/db/models/query.py", line 1270, in _insert
    return query.get_compiler(using=using).execute_sql(returning_fields)
  File "/home/app_admin/venv_private_diary/lib64/python3.8/site-packages/django/db/models/sql/compiler.py", line 1416, in execute_sql
    cursor.execute(sql, params)
  File "/home/app_admin/venv_private_diary/lib64/python3.8/site-packages/django/db/backends/utils.py", line 66, in execute
    return self._execute_with_wrappers(sql, params, many=False, executor=self._execute)
  File "/home/app_admin/venv_private_diary/lib64/python3.8/site-packages/django/db/backends/utils.py", line 75, in _execute_with_wrappers
    return executor(sql, params, many, context)
  File "/home/app_admin/venv_private_diary/lib64/python3.8/site-packages/django/db/backends/utils.py", line 84, in _execute
    return self.cursor.execute(sql, params)
  File "/home/app_admin/venv_private_diary/lib64/python3.8/site-packages/django/db/utils.py", line 90, in __exit__
    raise dj_exc_value.with_traceback(traceback) from exc_value
  File "/home/app_admin/venv_private_diary/lib64/python3.8/site-packages/django/db/backends/utils.py", line 84, in _execute
    return self.cursor.execute(sql, params)
django.db.utils.IntegrityError: リレーション"diary_diary"の列"event"のNULL値がが非NULL制約に違反しています
DETAIL:  失敗した行は(26, fasdfasd, fasd, , , , 2023-06-27 02:52:03.239646+00, 2023-06-27 02:52:03.239666+00, 14, null, , null, null, null, null, null)を含みます

2023-06-27 11:52:54,592	[ERROR]	/home/app_admin/venv_private_diary/lib64/python3.8/site-packages/django/utils/log.py(Line:224)	Internal Server Error: /diary-create/
Traceback (most recent call last):
  File "/home/app_admin/venv_private_diary/lib64/python3.8/site-packages/django/db/backends/utils.py", line 84, in _execute
    return self.cursor.execute(sql, params)
psycopg2.errors.NotNullViolation: リレーション"diary_diary"の列"event"のNULL値がが非NULL制約に違反しています
DETAIL:  失敗した行は(27, sdf, sadf, , , , 2023-06-27 02:52:54.589668+00, 2023-06-27 02:52:54.589685+00, 14, null, , null, null, null, null, null)を含みます


The above exception was the direct cause of the following exception:

Traceback (most recent call last):
  File "/home/app_admin/venv_private_diary/lib64/python3.8/site-packages/django/core/handlers/exception.py", line 47, in inner
    response = get_response(request)
  File "/home/app_admin/venv_private_diary/lib64/python3.8/site-packages/django/core/handlers/base.py", line 181, in _get_response
    response = wrapped_callback(request, *callback_args, **callback_kwargs)
  File "/home/app_admin/venv_private_diary/lib64/python3.8/site-packages/django/views/generic/base.py", line 70, in view
    return self.dispatch(request, *args, **kwargs)
  File "/home/app_admin/venv_private_diary/lib64/python3.8/site-packages/django/contrib/auth/mixins.py", line 71, in dispatch
    return super().dispatch(request, *args, **kwargs)
  File "/home/app_admin/venv_private_diary/lib64/python3.8/site-packages/django/views/generic/base.py", line 98, in dispatch
    return handler(request, *args, **kwargs)
  File "/home/app_admin/venv_private_diary/lib64/python3.8/site-packages/django/views/generic/edit.py", line 172, in post
    return super().post(request, *args, **kwargs)
  File "/home/app_admin/venv_private_diary/lib64/python3.8/site-packages/django/views/generic/edit.py", line 142, in post
    return self.form_valid(form)
  File "/home/app_admin/venv_private_diary/private_diary/diary/views.py", line 80, in form_valid
    diary.save()
  File "/home/app_admin/venv_private_diary/lib64/python3.8/site-packages/django/db/models/base.py", line 726, in save
    self.save_base(using=using, force_insert=force_insert,
  File "/home/app_admin/venv_private_diary/lib64/python3.8/site-packages/django/db/models/base.py", line 763, in save_base
    updated = self._save_table(
  File "/home/app_admin/venv_private_diary/lib64/python3.8/site-packages/django/db/models/base.py", line 868, in _save_table
    results = self._do_insert(cls._base_manager, using, fields, returning_fields, raw)
  File "/home/app_admin/venv_private_diary/lib64/python3.8/site-packages/django/db/models/base.py", line 906, in _do_insert
    return manager._insert(
  File "/home/app_admin/venv_private_diary/lib64/python3.8/site-packages/django/db/models/manager.py", line 85, in manager_method
    return getattr(self.get_queryset(), name)(*args, **kwargs)
  File "/home/app_admin/venv_private_diary/lib64/python3.8/site-packages/django/db/models/query.py", line 1270, in _insert
    return query.get_compiler(using=using).execute_sql(returning_fields)
  File "/home/app_admin/venv_private_diary/lib64/python3.8/site-packages/django/db/models/sql/compiler.py", line 1416, in execute_sql
    cursor.execute(sql, params)
  File "/home/app_admin/venv_private_diary/lib64/python3.8/site-packages/django/db/backends/utils.py", line 66, in execute
    return self._execute_with_wrappers(sql, params, many=False, executor=self._execute)
  File "/home/app_admin/venv_private_diary/lib64/python3.8/site-packages/django/db/backends/utils.py", line 75, in _execute_with_wrappers
    return executor(sql, params, many, context)
  File "/home/app_admin/venv_private_diary/lib64/python3.8/site-packages/django/db/backends/utils.py", line 84, in _execute
    return self.cursor.execute(sql, params)
  File "/home/app_admin/venv_private_diary/lib64/python3.8/site-packages/django/db/utils.py", line 90, in __exit__
    raise dj_exc_value.with_traceback(traceback) from exc_value
  File "/home/app_admin/venv_private_diary/lib64/python3.8/site-packages/django/db/backends/utils.py", line 84, in _execute
    return self.cursor.execute(sql, params)
django.db.utils.IntegrityError: リレーション"diary_diary"の列"event"のNULL値がが非NULL制約に違反しています
DETAIL:  失敗した行は(27, sdf, sadf, , , , 2023-06-27 02:52:54.589668+00, 2023-06-27 02:52:54.589685+00, 14, null, , null, null, null, null, null)を含みます

2023-06-27 11:54:07,491	[ERROR]	/home/app_admin/venv_private_diary/lib64/python3.8/site-packages/django/utils/log.py(Line:224)	Internal Server Error: /diary-create/
Traceback (most recent call last):
  File "/home/app_admin/venv_private_diary/lib64/python3.8/site-packages/django/db/backends/utils.py", line 84, in _execute
    return self.cursor.execute(sql, params)
psycopg2.errors.NotNullViolation: リレーション"diary_diary"の列"event"のNULL値がが非NULL制約に違反しています
DETAIL:  失敗した行は(28, sdf, sadf, , , , 2023-06-27 02:54:07.489464+00, 2023-06-27 02:54:07.489482+00, 14, null, , null, null, null, null, null)を含みます


The above exception was the direct cause of the following exception:

Traceback (most recent call last):
  File "/home/app_admin/venv_private_diary/lib64/python3.8/site-packages/django/core/handlers/exception.py", line 47, in inner
    response = get_response(request)
  File "/home/app_admin/venv_private_diary/lib64/python3.8/site-packages/django/core/handlers/base.py", line 181, in _get_response
    response = wrapped_callback(request, *callback_args, **callback_kwargs)
  File "/home/app_admin/venv_private_diary/lib64/python3.8/site-packages/django/views/generic/base.py", line 70, in view
    return self.dispatch(request, *args, **kwargs)
  File "/home/app_admin/venv_private_diary/lib64/python3.8/site-packages/django/contrib/auth/mixins.py", line 71, in dispatch
    return super().dispatch(request, *args, **kwargs)
  File "/home/app_admin/venv_private_diary/lib64/python3.8/site-packages/django/views/generic/base.py", line 98, in dispatch
    return handler(request, *args, **kwargs)
  File "/home/app_admin/venv_private_diary/lib64/python3.8/site-packages/django/views/generic/edit.py", line 172, in post
    return super().post(request, *args, **kwargs)
  File "/home/app_admin/venv_private_diary/lib64/python3.8/site-packages/django/views/generic/edit.py", line 142, in post
    return self.form_valid(form)
  File "/home/app_admin/venv_private_diary/private_diary/diary/views.py", line 80, in form_valid
    diary.save()
  File "/home/app_admin/venv_private_diary/lib64/python3.8/site-packages/django/db/models/base.py", line 726, in save
    self.save_base(using=using, force_insert=force_insert,
  File "/home/app_admin/venv_private_diary/lib64/python3.8/site-packages/django/db/models/base.py", line 763, in save_base
    updated = self._save_table(
  File "/home/app_admin/venv_private_diary/lib64/python3.8/site-packages/django/db/models/base.py", line 868, in _save_table
    results = self._do_insert(cls._base_manager, using, fields, returning_fields, raw)
  File "/home/app_admin/venv_private_diary/lib64/python3.8/site-packages/django/db/models/base.py", line 906, in _do_insert
    return manager._insert(
  File "/home/app_admin/venv_private_diary/lib64/python3.8/site-packages/django/db/models/manager.py", line 85, in manager_method
    return getattr(self.get_queryset(), name)(*args, **kwargs)
  File "/home/app_admin/venv_private_diary/lib64/python3.8/site-packages/django/db/models/query.py", line 1270, in _insert
    return query.get_compiler(using=using).execute_sql(returning_fields)
  File "/home/app_admin/venv_private_diary/lib64/python3.8/site-packages/django/db/models/sql/compiler.py", line 1416, in execute_sql
    cursor.execute(sql, params)
  File "/home/app_admin/venv_private_diary/lib64/python3.8/site-packages/django/db/backends/utils.py", line 66, in execute
    return self._execute_with_wrappers(sql, params, many=False, executor=self._execute)
  File "/home/app_admin/venv_private_diary/lib64/python3.8/site-packages/django/db/backends/utils.py", line 75, in _execute_with_wrappers
    return executor(sql, params, many, context)
  File "/home/app_admin/venv_private_diary/lib64/python3.8/site-packages/django/db/backends/utils.py", line 84, in _execute
    return self.cursor.execute(sql, params)
  File "/home/app_admin/venv_private_diary/lib64/python3.8/site-packages/django/db/utils.py", line 90, in __exit__
    raise dj_exc_value.with_traceback(traceback) from exc_value
  File "/home/app_admin/venv_private_diary/lib64/python3.8/site-packages/django/db/backends/utils.py", line 84, in _execute
    return self.cursor.execute(sql, params)
django.db.utils.IntegrityError: リレーション"diary_diary"の列"event"のNULL値がが非NULL制約に違反しています
DETAIL:  失敗した行は(28, sdf, sadf, , , , 2023-06-27 02:54:07.489464+00, 2023-06-27 02:54:07.489482+00, 14, null, , null, null, null, null, null)を含みます

2023-06-27 11:54:52,092	[ERROR]	/home/app_admin/venv_private_diary/lib64/python3.8/site-packages/django/utils/log.py(Line:224)	Internal Server Error: /diary-create/
Traceback (most recent call last):
  File "/home/app_admin/venv_private_diary/lib64/python3.8/site-packages/django/db/backends/utils.py", line 84, in _execute
    return self.cursor.execute(sql, params)
psycopg2.errors.NotNullViolation: リレーション"diary_diary"の列"event"のNULL値がが非NULL制約に違反しています
DETAIL:  失敗した行は(29, asdf, sdf, , , , 2023-06-27 02:54:52.090362+00, 2023-06-27 02:54:52.09038+00, 14, null, , null, null, null, null, null)を含みます


The above exception was the direct cause of the following exception:

Traceback (most recent call last):
  File "/home/app_admin/venv_private_diary/lib64/python3.8/site-packages/django/core/handlers/exception.py", line 47, in inner
    response = get_response(request)
  File "/home/app_admin/venv_private_diary/lib64/python3.8/site-packages/django/core/handlers/base.py", line 181, in _get_response
    response = wrapped_callback(request, *callback_args, **callback_kwargs)
  File "/home/app_admin/venv_private_diary/lib64/python3.8/site-packages/django/views/generic/base.py", line 70, in view
    return self.dispatch(request, *args, **kwargs)
  File "/home/app_admin/venv_private_diary/lib64/python3.8/site-packages/django/contrib/auth/mixins.py", line 71, in dispatch
    return super().dispatch(request, *args, **kwargs)
  File "/home/app_admin/venv_private_diary/lib64/python3.8/site-packages/django/views/generic/base.py", line 98, in dispatch
    return handler(request, *args, **kwargs)
  File "/home/app_admin/venv_private_diary/lib64/python3.8/site-packages/django/views/generic/edit.py", line 172, in post
    return super().post(request, *args, **kwargs)
  File "/home/app_admin/venv_private_diary/lib64/python3.8/site-packages/django/views/generic/edit.py", line 142, in post
    return self.form_valid(form)
  File "/home/app_admin/venv_private_diary/private_diary/diary/views.py", line 80, in form_valid
    diary.save()
  File "/home/app_admin/venv_private_diary/lib64/python3.8/site-packages/django/db/models/base.py", line 726, in save
    self.save_base(using=using, force_insert=force_insert,
  File "/home/app_admin/venv_private_diary/lib64/python3.8/site-packages/django/db/models/base.py", line 763, in save_base
    updated = self._save_table(
  File "/home/app_admin/venv_private_diary/lib64/python3.8/site-packages/django/db/models/base.py", line 868, in _save_table
    results = self._do_insert(cls._base_manager, using, fields, returning_fields, raw)
  File "/home/app_admin/venv_private_diary/lib64/python3.8/site-packages/django/db/models/base.py", line 906, in _do_insert
    return manager._insert(
  File "/home/app_admin/venv_private_diary/lib64/python3.8/site-packages/django/db/models/manager.py", line 85, in manager_method
    return getattr(self.get_queryset(), name)(*args, **kwargs)
  File "/home/app_admin/venv_private_diary/lib64/python3.8/site-packages/django/db/models/query.py", line 1270, in _insert
    return query.get_compiler(using=using).execute_sql(returning_fields)
  File "/home/app_admin/venv_private_diary/lib64/python3.8/site-packages/django/db/models/sql/compiler.py", line 1416, in execute_sql
    cursor.execute(sql, params)
  File "/home/app_admin/venv_private_diary/lib64/python3.8/site-packages/django/db/backends/utils.py", line 66, in execute
    return self._execute_with_wrappers(sql, params, many=False, executor=self._execute)
  File "/home/app_admin/venv_private_diary/lib64/python3.8/site-packages/django/db/backends/utils.py", line 75, in _execute_with_wrappers
    return executor(sql, params, many, context)
  File "/home/app_admin/venv_private_diary/lib64/python3.8/site-packages/django/db/backends/utils.py", line 84, in _execute
    return self.cursor.execute(sql, params)
  File "/home/app_admin/venv_private_diary/lib64/python3.8/site-packages/django/db/utils.py", line 90, in __exit__
    raise dj_exc_value.with_traceback(traceback) from exc_value
  File "/home/app_admin/venv_private_diary/lib64/python3.8/site-packages/django/db/backends/utils.py", line 84, in _execute
    return self.cursor.execute(sql, params)
django.db.utils.IntegrityError: リレーション"diary_diary"の列"event"のNULL値がが非NULL制約に違反しています
DETAIL:  失敗した行は(29, asdf, sdf, , , , 2023-06-27 02:54:52.090362+00, 2023-06-27 02:54:52.09038+00, 14, null, , null, null, null, null, null)を含みます

2023-06-27 11:57:25,784	[ERROR]	/home/app_admin/venv_private_diary/lib64/python3.8/site-packages/django/utils/log.py(Line:224)	Internal Server Error: /diary-create/
Traceback (most recent call last):
  File "/home/app_admin/venv_private_diary/lib64/python3.8/site-packages/django/db/backends/utils.py", line 84, in _execute
    return self.cursor.execute(sql, params)
psycopg2.errors.NotNullViolation: リレーション"diary_diary"の列"event"のNULL値がが非NULL制約に違反しています
DETAIL:  失敗した行は(30, s, s, kuma.jpeg, , , 2023-06-27 02:57:25.782208+00, 2023-06-27 02:57:25.782233+00, 14, null, , null, null, null, null, null)を含みます


The above exception was the direct cause of the following exception:

Traceback (most recent call last):
  File "/home/app_admin/venv_private_diary/lib64/python3.8/site-packages/django/core/handlers/exception.py", line 47, in inner
    response = get_response(request)
  File "/home/app_admin/venv_private_diary/lib64/python3.8/site-packages/django/core/handlers/base.py", line 181, in _get_response
    response = wrapped_callback(request, *callback_args, **callback_kwargs)
  File "/home/app_admin/venv_private_diary/lib64/python3.8/site-packages/django/views/generic/base.py", line 70, in view
    return self.dispatch(request, *args, **kwargs)
  File "/home/app_admin/venv_private_diary/lib64/python3.8/site-packages/django/contrib/auth/mixins.py", line 71, in dispatch
    return super().dispatch(request, *args, **kwargs)
  File "/home/app_admin/venv_private_diary/lib64/python3.8/site-packages/django/views/generic/base.py", line 98, in dispatch
    return handler(request, *args, **kwargs)
  File "/home/app_admin/venv_private_diary/lib64/python3.8/site-packages/django/views/generic/edit.py", line 172, in post
    return super().post(request, *args, **kwargs)
  File "/home/app_admin/venv_private_diary/lib64/python3.8/site-packages/django/views/generic/edit.py", line 142, in post
    return self.form_valid(form)
  File "/home/app_admin/venv_private_diary/private_diary/diary/views.py", line 80, in form_valid
    diary.save()
  File "/home/app_admin/venv_private_diary/lib64/python3.8/site-packages/django/db/models/base.py", line 726, in save
    self.save_base(using=using, force_insert=force_insert,
  File "/home/app_admin/venv_private_diary/lib64/python3.8/site-packages/django/db/models/base.py", line 763, in save_base
    updated = self._save_table(
  File "/home/app_admin/venv_private_diary/lib64/python3.8/site-packages/django/db/models/base.py", line 868, in _save_table
    results = self._do_insert(cls._base_manager, using, fields, returning_fields, raw)
  File "/home/app_admin/venv_private_diary/lib64/python3.8/site-packages/django/db/models/base.py", line 906, in _do_insert
    return manager._insert(
  File "/home/app_admin/venv_private_diary/lib64/python3.8/site-packages/django/db/models/manager.py", line 85, in manager_method
    return getattr(self.get_queryset(), name)(*args, **kwargs)
  File "/home/app_admin/venv_private_diary/lib64/python3.8/site-packages/django/db/models/query.py", line 1270, in _insert
    return query.get_compiler(using=using).execute_sql(returning_fields)
  File "/home/app_admin/venv_private_diary/lib64/python3.8/site-packages/django/db/models/sql/compiler.py", line 1416, in execute_sql
    cursor.execute(sql, params)
  File "/home/app_admin/venv_private_diary/lib64/python3.8/site-packages/django/db/backends/utils.py", line 66, in execute
    return self._execute_with_wrappers(sql, params, many=False, executor=self._execute)
  File "/home/app_admin/venv_private_diary/lib64/python3.8/site-packages/django/db/backends/utils.py", line 75, in _execute_with_wrappers
    return executor(sql, params, many, context)
  File "/home/app_admin/venv_private_diary/lib64/python3.8/site-packages/django/db/backends/utils.py", line 84, in _execute
    return self.cursor.execute(sql, params)
  File "/home/app_admin/venv_private_diary/lib64/python3.8/site-packages/django/db/utils.py", line 90, in __exit__
    raise dj_exc_value.with_traceback(traceback) from exc_value
  File "/home/app_admin/venv_private_diary/lib64/python3.8/site-packages/django/db/backends/utils.py", line 84, in _execute
    return self.cursor.execute(sql, params)
django.db.utils.IntegrityError: リレーション"diary_diary"の列"event"のNULL値がが非NULL制約に違反しています
DETAIL:  失敗した行は(30, s, s, kuma.jpeg, , , 2023-06-27 02:57:25.782208+00, 2023-06-27 02:57:25.782233+00, 14, null, , null, null, null, null, null)を含みます

2023-06-27 12:02:51,019	[ERROR]	/home/app_admin/venv_private_diary/lib64/python3.8/site-packages/django/utils/log.py(Line:224)	Internal Server Error: /diary-create/
Traceback (most recent call last):
  File "/home/app_admin/venv_private_diary/lib64/python3.8/site-packages/django/db/backends/utils.py", line 84, in _execute
    return self.cursor.execute(sql, params)
psycopg2.errors.NotNullViolation: リレーション"diary_diary"の列"event"のNULL値がが非NULL制約に違反しています
DETAIL:  失敗した行は(31, sd, asd, , , , 2023-06-27 03:02:51.017945+00, 2023-06-27 03:02:51.017964+00, 14, null, , null)を含みます


The above exception was the direct cause of the following exception:

Traceback (most recent call last):
  File "/home/app_admin/venv_private_diary/lib64/python3.8/site-packages/django/core/handlers/exception.py", line 47, in inner
    response = get_response(request)
  File "/home/app_admin/venv_private_diary/lib64/python3.8/site-packages/django/core/handlers/base.py", line 181, in _get_response
    response = wrapped_callback(request, *callback_args, **callback_kwargs)
  File "/home/app_admin/venv_private_diary/lib64/python3.8/site-packages/django/views/generic/base.py", line 70, in view
    return self.dispatch(request, *args, **kwargs)
  File "/home/app_admin/venv_private_diary/lib64/python3.8/site-packages/django/contrib/auth/mixins.py", line 71, in dispatch
    return super().dispatch(request, *args, **kwargs)
  File "/home/app_admin/venv_private_diary/lib64/python3.8/site-packages/django/views/generic/base.py", line 98, in dispatch
    return handler(request, *args, **kwargs)
  File "/home/app_admin/venv_private_diary/lib64/python3.8/site-packages/django/views/generic/edit.py", line 172, in post
    return super().post(request, *args, **kwargs)
  File "/home/app_admin/venv_private_diary/lib64/python3.8/site-packages/django/views/generic/edit.py", line 142, in post
    return self.form_valid(form)
  File "/home/app_admin/venv_private_diary/private_diary/diary/views.py", line 80, in form_valid
    diary.save()
  File "/home/app_admin/venv_private_diary/lib64/python3.8/site-packages/django/db/models/base.py", line 726, in save
    self.save_base(using=using, force_insert=force_insert,
  File "/home/app_admin/venv_private_diary/lib64/python3.8/site-packages/django/db/models/base.py", line 763, in save_base
    updated = self._save_table(
  File "/home/app_admin/venv_private_diary/lib64/python3.8/site-packages/django/db/models/base.py", line 868, in _save_table
    results = self._do_insert(cls._base_manager, using, fields, returning_fields, raw)
  File "/home/app_admin/venv_private_diary/lib64/python3.8/site-packages/django/db/models/base.py", line 906, in _do_insert
    return manager._insert(
  File "/home/app_admin/venv_private_diary/lib64/python3.8/site-packages/django/db/models/manager.py", line 85, in manager_method
    return getattr(self.get_queryset(), name)(*args, **kwargs)
  File "/home/app_admin/venv_private_diary/lib64/python3.8/site-packages/django/db/models/query.py", line 1270, in _insert
    return query.get_compiler(using=using).execute_sql(returning_fields)
  File "/home/app_admin/venv_private_diary/lib64/python3.8/site-packages/django/db/models/sql/compiler.py", line 1416, in execute_sql
    cursor.execute(sql, params)
  File "/home/app_admin/venv_private_diary/lib64/python3.8/site-packages/django/db/backends/utils.py", line 66, in execute
    return self._execute_with_wrappers(sql, params, many=False, executor=self._execute)
  File "/home/app_admin/venv_private_diary/lib64/python3.8/site-packages/django/db/backends/utils.py", line 75, in _execute_with_wrappers
    return executor(sql, params, many, context)
  File "/home/app_admin/venv_private_diary/lib64/python3.8/site-packages/django/db/backends/utils.py", line 84, in _execute
    return self.cursor.execute(sql, params)
  File "/home/app_admin/venv_private_diary/lib64/python3.8/site-packages/django/db/utils.py", line 90, in __exit__
    raise dj_exc_value.with_traceback(traceback) from exc_value
  File "/home/app_admin/venv_private_diary/lib64/python3.8/site-packages/django/db/backends/utils.py", line 84, in _execute
    return self.cursor.execute(sql, params)
django.db.utils.IntegrityError: リレーション"diary_diary"の列"event"のNULL値がが非NULL制約に違反しています
DETAIL:  失敗した行は(31, sd, asd, , , , 2023-06-27 03:02:51.017945+00, 2023-06-27 03:02:51.017964+00, 14, null, , null)を含みます

2023-06-27 12:16:29,753	[ERROR]	/home/app_admin/venv_private_diary/lib64/python3.8/site-packages/django/core/handlers/exception.py(Line:99)	Invalid HTTP_HOST header: '18.213.182.163'. You may need to add '18.213.182.163' to ALLOWED_HOSTS.
2023-06-27 12:16:29,754	[WARNING]	/home/app_admin/venv_private_diary/lib64/python3.8/site-packages/django/utils/log.py(Line:224)	Bad Request: /
2023-06-27 12:17:01,266	[WARNING]	/home/app_admin/venv_private_diary/lib64/python3.8/site-packages/django/utils/log.py(Line:224)	Not Found: /favicon.ico
2023-06-27 12:32:16,310	[WARNING]	/home/app_admin/venv_private_diary/lib64/python3.8/site-packages/django/utils/log.py(Line:224)	Not Found: /nginx-logo.png
2023-06-27 12:32:16,319	[WARNING]	/home/app_admin/venv_private_diary/lib64/python3.8/site-packages/django/utils/log.py(Line:224)	Not Found: /poweredby.png
2023-06-27 12:52:06,705	[ERROR]	/home/app_admin/venv_private_diary/lib64/python3.8/site-packages/django/core/handlers/exception.py(Line:99)	Invalid HTTP_HOST header: '18.213.182.163'. You may need to add '18.213.182.163' to ALLOWED_HOSTS.
2023-06-27 12:52:06,706	[WARNING]	/home/app_admin/venv_private_diary/lib64/python3.8/site-packages/django/utils/log.py(Line:224)	Bad Request: /.env
2023-06-27 12:52:07,190	[ERROR]	/home/app_admin/venv_private_diary/lib64/python3.8/site-packages/django/core/handlers/exception.py(Line:99)	Invalid HTTP_HOST header: '18.213.182.163'. You may need to add '18.213.182.163' to ALLOWED_HOSTS.
2023-06-27 12:52:07,191	[WARNING]	/home/app_admin/venv_private_diary/lib64/python3.8/site-packages/django/utils/log.py(Line:224)	Bad Request: /
2023-06-27 13:06:06,240	[ERROR]	/home/app_admin/venv_private_diary/lib64/python3.8/site-packages/django/core/handlers/exception.py(Line:99)	Invalid HTTP_HOST header: '18.213.182.163'. You may need to add '18.213.182.163' to ALLOWED_HOSTS.
2023-06-27 13:06:06,241	[WARNING]	/home/app_admin/venv_private_diary/lib64/python3.8/site-packages/django/utils/log.py(Line:224)	Bad Request: /
